Workbook

Sheet Características de CRI - LOGOS
A1: Operação - Apelido | B1: Status | C1: Emissão | D1: Papel | E1: Código IF | F1: Série | G1: Escriturador | H1: Data de Emiss„o | I1: Data de Vencimento | J1: Data Final de DistribuiÁ„o | K1: Data de Resgate Antecipado | L1: Tipo da Oferta | M1: Data da 1a Integralizaçāo | N1: ISIN | O1: Estrutura/ | P1: Investidor | Q1: Emissor | R1: Agente Fiduci·rio | S1: Coordenador Líder | T1: Cedente | U1: PU Emissāo | V1: Ágio | W1: Qtd Emitida | X1: Volume Emiss„o | Y1: Qtd Integralizada | Z1: Observaçāo | AA1: Saldo Devedor | AB1: Gestão | AC1: Servicing | AD1: Indexador | AE1: % Taxa Flutuante | AF1: Taxa de Juros PrÈ/Spread | AG1: Pagamento de Juros | AH1: AmortizaÁ„o
A2: 1ª Série - Paysage | B2: Resgatada Antecipadamente | C2: 1 | D2: CRI | E2: 14J0107228 | F2: 1 | G2: Oliveira Trust | H2: 41932 | I2: 45555 | J2: 42112 | K2: 44459 | L2: CVM 476 | M2: 41936 | O2: Cessāo Fiduciária | P2: PH | Q2: LOGOS COMPANHIA SECURITIZADORA S/A | R2: PENTAGONO DTVM SA | S2: BRL Trust DTVM | T2: Paysage | U2: 1000000 | W2: 10 | X2: 10000000 | Y2: 10 | AD2: IPCA | AF2: 0.09 | AG2: 360 | AH2: Percentual variavel, periodos uniformes, sobre valor remanescente
A3: 2ª Série - Paysage | B3: Resgatada Antecipadamente | C3: 1 | D3: CRI | E3: 14L0093591 | F3: 2 | G3: Oliveira Trust | H3: 41988 | I3: 44885 | J3: 42168 | L3: CVM 476 | M3: 41992 | O3: Cessāo Fiduciária | P3: Nexus | Q3: LOGOS COMPANHIA SECURITIZADORA S/A | R3: PENTAGONO DTVM SA | S3: BRL Trust DTVM | T3: Paysage | U3: 304305.66 | W3: 42 | X3: =W3*U3 -> 12780838 | Y3: 42 | AD3: IPCA | AF3: 0.095 | AG3: 360 | AH3: Percentual variavel, periodos uniformes, sobre valor remanescente
A4: 3ª Série - Paysage | B4: Resgatada Antecipadamente | C4: 1 | D4: CRI | E4: 15F0494185 | F4: 3 | G4: Oliveira Trust | H4: 42160 | I4: 45036 | J4: 42343 | L4: CVM 476 | M4: 42164 | O4: Cessāo Fiduciária | P4: Nexus e BoticárioPrev | Q4: LOGOS COMPANHIA SECURITIZADORA S/A | R4: PENTAGONO DTVM SA | S4: BRL Trust DTVM | T4: Paysage | U4: 303030.3 | W4: 66 | X4: =W4*U4 -> 20000000 | Y4: 66 | AD4: IPCA | AF4: 0.095 | AG4: 360 | AH4: Percentual variavel, periodos uniformes, sobre valor remanescente
A5: 4ª Série - Paysage | B5: Ativo | C5: 1 | D5: CRI | E5: 15L0542115 | F5: 4 | G5: Oliveira Trust | H5: 42348 | I5: 47684 | J5: 42539 | L5: CVM 476 | N5: BRLGOSCRI0T7 | O5: Cessāo Fiduciária | P5: PH | Q5: LOGOS COMPANHIA SECURITIZADORA S/A | R5: PENTAGONO DTVM SA | T5: Paysage | U5: 1000000 | V5: 0 | W5: 5 | X5: 5000000 | Y5: 5 | AA5: 2658663 | AB5: 9652.32 | AC5: 837.68 | AD5: IPCA | AF5: 0.11 | AG5: 360 | AH5: Percentual variavel, periodos uniformes, sobre valor remanescente
A6: 5ª e 6ª Séries - Paysage | B6: Resgatada Antecipadamente | C6: 1 | D6: CRI | E6: 15L0622052 | F6: 5 | G6: Oliveira Trust | H6: 42353 | I6: 44545 | J6: 42536 | K6: 43175 | L6: CVM 476 | O6: Cessāo Fiduciária | P6: Nexus e BoticárioPrev | Q6: LOGOS COMPANHIA SECURITIZADORA S/A | R6: PENTAGONO DTVM SA | S6: BRL Trust DTVM | T6: Paysage | U6: 10000 | W6: 2450 | X6: =W6*U6 -> 24500000 | Y6: 2450 | AD6: IPCA | AF6: 0.085 | AG6: 360 | AH6: Percentual variavel, periodos uniformes, sobre valor remanescente
A7: 5ª e 6ª Séries - Paysage | B7: Resgatada Antecipadamente | C7: 1 | D7: CRI | E7: 15L0622157 | F7: 6 | G7: Oliveira Trust | H7: 42353 | I7: 45703 | J7: 42536 | K7: 43175 | L7: CVM 476 | O7: Cessāo Fiduciária | P7: Nexus e BoticárioPrev | Q7: LOGOS COMPANHIA SECURITIZADORA S/A | R7: PENTAGONO DTVM SA | S7: BRL Trust DTVM | T7: Paysage | U7: 10000 | W7: 1050 | X7: =W7*U7 -> 10500000 | Y7: 1050 | AD7: IPCA | AF7: 0.135 | AG7: 360 | AH7: Percentual variavel, periodos uniformes, sobre valor remanescente
A8: 7ª e 8ª Séries - Paysage | B8: Resgatada Antecipadamente | C8: 1 | D8: CRI | E8: 16D0138913 | F8: 7 | G8: Oliveira Trust | H8: 42472 | I8: 46127 | J8: 42502 | K8: 44392 | L8: CVM 476 | O8: Cessāo Fiduciária | P8: Nexus e BoticárioPrev | Q8: LOGOS COMPANHIA SECURITIZADORA S/A | R8: PENTAGONO DTVM SA | S8: BRL Trust DTVM | T8: Paysage | U8: 10000 | W8: 1841 | X8: =W8*U8 -> 18410000 | Y8: 1841 | AD8: IPCA | AF8: 0.085 | AG8: 360 | AH8: Percentual variavel, periodos uniformes, sobre valor remanescente
A9: 7ª e 8ª Séries - Paysage | B9: Resgatada Antecipadamente | C9: 1 | D9: CRI | E9: 16D0144796 | F9: 8 | G9: Oliveira Trust | H9: 42472 | I9: 44392 | J9: 42502 | K9: 44392 | L9: CVM 476 | O9: Cessāo Fiduciária | P9: Nexus e BoticárioPrev | Q9: LOGOS COMPANHIA SECURITIZADORA S/A | R9: PENTAGONO DTVM SA | S9: BRL Trust DTVM | T9: Paysage | U9: 10000 | W9: 789 | X9: =W9*U9 -> 7890000 | Y9: 789 | AD9: IPCA | AF9: 0.1375 | AG9: 360 | AH9: Percentual variavel, periodos uniformes, sobre valor remanescente
A10: 9ª e 10ª Séries - Premoaço | B10: Resgatada Antecipadamente | C10: 1 | D10: CRI | E10: 16I0999053 | F10: 9 | G10: Oliveira Trust | H10: 42643 | I10: 45458 | L10: CVM 476 | M10: 42660 | O10: BTS, Contrato de Cessāo Aluguel | P10: Nexus e BoticárioPrev | Q10: LOGOS COMPANHIA SECURITIZADORA S/A | R10: PENTAGONO DTVM SA | S10: CM Capital Markets | T10: Premoaço | U10: 1 | W10: 13200000 | X10: =W10*U10 -> 13200000 | AD10: CDI | AE10: 100 | AF10: 0.015 | AG10: 252 | AH10: Percentual variavel, periodos uniformes, sobre valor remanescente
A11: 9ª e 10ª Séries - Premoaço | B11: Resgatada Antecipadamente | C11: 1 | D11: CRI | E11: 16I0999358 | F11: 10 | G11: Oliveira Trust | H11: 42643 | I11: 45915 | L11: CVM 476 | M11: 42660 | O11: BTS, Contrato de Cessāo Aluguel | P11: Nexus e BoticárioPrev | Q11: LOGOS COMPANHIA SECURITIZADORA S/A | R11: PENTAGONO DTVM SA | S11: CM Capital Markets | T11: Premoaço | U11: 1 | W11: 5660000 | X11: =W11*U11 -> 5660000 | AD11: CDI | AE11: 100 | AF11: 0.0947 | AG11: 252 | AH11: Percentual variavel, periodos uniformes, sobre valor remanescente
A12: 11ª e 12ª Séries - Paysage | B12: Resgatada Antecipadamente | C12: 1 | D12: CRI | E12: 17B0186197 | F12: 11 | G12: Oliveira Trust | H12: 42782 | I12: 45427 | J12: 42967 | L12: CVM 476 | O12: Cessāo Fiduciária | P12: PH | Q12: LOGOS COMPANHIA SECURITIZADORA S/A | R12: PENTAGONO DTVM SA | S12: CM Capital Markets | T12: Paysage | U12: 1 | W12: 14000000 | X12: =W12*U12 -> 14000000 | AD12: IPCA | AF12: 0.085 | AG12: 360 | AH12: Percentual variavel, periodos uniformes, sobre valor remanescente
A13: 11ª e 12ª Séries - Paysage | B13: Resgatada Antecipadamente | C13: 1 | D13: CRI | E13: 17B0186441 | F13: 12 | G13: Oliveira Trust | H13: 42782 | I13: 47041 | J13: 42967 | L13: CVM 476 | O13: Cessāo Fiduciária | P13: PH | Q13: LOGOS COMPANHIA SECURITIZADORA S/A | R13: PENTAGONO DTVM SA | S13: CM Capital Markets | T13: Paysage | U13: 1 | W13: 6000000 | X13: =W13*U13 -> 6000000 | Y13: 5866847 | Z13: Solicitar o cancelamento na B3 | AD13: IPCA | AF13: 0.1388 | AG13: 360 | AH13: Percentual variavel, periodos uniformes, sobre valor remanescente
A14: 13ª, 14ª, 15ª Séries - Helio Winter | B14: Resgatada Antecipadamente | C14: 1 | D14: CRI | E14: 17B0221371 | F14: 13 | G14: Oliveira Trust | H14: 42786 | I14: 46006 | J14: 42967 | L14: CVM 476 | O14: Cessāo Fiduciária | Q14: LOGOS COMPANHIA SECURITIZADORA S/A | R14: PENTAGONO DTVM SA | S14: CM Capital Markets | T14: Helio Winter | U14: 1 | W14: 2000000 | X14: =W14*U14 -> 2000000 | Y14: 2000000 | AD14: IGP-M | AF14: 0.09 | AG14: 360 | AH14: Percentual variavel, periodos uniformes, sobre valor remanescente
A15: 13ª, 14ª, 15ª Séries - Helio Winter | B15: Resgatada Antecipadamente | C15: 1 | D15: CRI | E15: 17B0221403 | F15: 14 | G15: Oliveira Trust | H15: 42786 | I15: 46006 | J15: 42967 | L15: CVM 476 | O15: Cessāo Fiduciária | Q15: LOGOS COMPANHIA SECURITIZADORA S/A | R15: PENTAGONO DTVM SA | S15: CM Capital Markets | T15: Helio Winter | U15: 1 | W15: 3000000 | X15: =W15*U15 -> 3000000 | Y15: 3000000 | AD15: IGP-M | AF15: 0.095 | AG15: 360 | AH15: Percentual variavel, periodos uniformes, sobre valor remanescente
A16: 13ª, 14ª, 15ª Séries - Helio Winter | B16: Resgatada Antecipadamente | C16: 1 | D16: CRI | E16: 17B0221509 | F16: 15 | G16: Oliveira Trust | H16: 42786 | I16: 46006 | L16: CVM 476 | O16: Cessāo Fiduciária | Q16: LOGOS COMPANHIA SECURITIZADORA S/A | R16: PENTAGONO DTVM SA | S16: CM Capital Markets | T16: Helio Winter | U16: 1 | W16: 1000000 | X16: =W16*U16 -> 1000000 | Y16: 1000000 | AD16: IGP-M | AF16: 0.12 | AG16: 360 | AH16: Percentual variavel, periodos uniformes, sobre valor remanescente
A17: 16ª e 17ª Séries - Paysage | B17: Resgatada Antecipadamente | C17: 1 | D17: CRI | E17: 18C0722274 | F17: 16 | G17: Oliveira Trust | H17: 43171 | I17: 46241 | J17: 43355 | K17: 44964 | L17: CVM 476 | O17: Cessāo Fiduciária | P17: Nexus e BoticárioPrev | Q17: LOGOS COMPANHIA SECURITIZADORA S/A | R17: PENTAGONO DTVM SA | S17: CM Capital Markets | T17: Paysage | U17: 10000 | W17: 2590 | X17: =W17*U17 -> 25900000 | Y17: 2590 | AD17: IPCA | AF17: 0.085 | AG17: 360 | AH17: Percentual variavel, periodos uniformes, sobre valor remanescente
A18: 16ª e 17ª Séries - Paysage | B18: Resgatada Antecipadamente | C18: 1 | D18: CRI | E18: 18C0722263 | F18: 17 | G18: Oliveira Trust | H18: 43171 | I18: 47975 | J18: 43355 | K18: 44964 | L18: CVM 476 | O18: Cessāo Fiduciária | P18: Nexus e BoticárioPrev | Q18: LOGOS COMPANHIA SECURITIZADORA S/A | R18: PENTAGONO DTVM SA | S18: CM Capital Markets | T18: Paysage | U18: 10000 | W18: 1110 | X18: =W18*U18 -> 11100000 | Y18: 1110 | AD18: IPCA | AF18: 0.135 | AG18: 360 | AH18: Percentual variavel, periodos uniformes, sobre valor remanescente
A19: 18ª, 19ª, 20ª Séries - Premoaço | B19: Ativo | C19: 1 | D19: CRI | E19: 18F0732035 | F19: 18 | G19: Oliveira Trust | H19: 43262 | I19: 47983 | J19: 43453 | L19: CVM 476 | N19: BRLGOSCRI0H2 | O19: BTS, Contrato de Cessāo Aluguel | P19: Nexus e BoticárioPrev | Q19: LOGOS COMPANHIA SECURITIZADORA S/A | R19: PENTAGONO DTVM SA | S19: CM Capital Markets | T19: Premoaço | U19: 1 | W19: 7200000 | X19: =W19*U19 -> 7200000 | Y19: 7200000 | AA19: 3755938.8 | AB19: 0 | AD19: CDI | AE19: 100 | AF19: 0.0525 | AG19: 252 | AH19: Percentual variavel, periodos uniformes, sobre valor remanescente
A20: 18ª, 19ª, 20ª Séries - Premoaço | B20: Ativo | C20: 1 | D20: CRI | E20: 17G1668350 | F20: 19 | G20: Oliveira Trust | H20: 42941 | I20: 45641 | J20: 43126 | L20: CVM 476 | N20: BRLGOSCRI0A7 | O20: BTS, Contrato de Cessāo Aluguel | P20: Nexus e BoticárioPrev | Q20: LOGOS COMPANHIA SECURITIZADORA S/A | R20: PENTAGONO DTVM SA | T20: Premoaço | U20: 1 | V20: 0 | W20: 18246106 | X20: 18246106 | Y20: 0 | AA20: 113590.63 | AB20: 10761.36 | AD20: DI | AE20: 100 | AF20: 0.015 | AG20: 252 | AH20: Percentual variavel, periodos uniformes, sobre valor remanescente
A21: 18ª, 19ª, 20ª Séries - Premoaço | B21: Ativo | C21: 1 | D21: CRI | E21: 17G1668137 | F21: 20 | G21: Oliveira Trust | H21: 42941 | I21: 46188 | J21: 43126 | L21: CVM 476 | N21: BRLGOSCRI0B5 | O21: BTS, Contrato de Cessāo Aluguel | P21: Nexus e BoticárioPrev | Q21: LOGOS COMPANHIA SECURITIZADORA S/A | R21: PENTAGONO DTVM SA | T21: Premoaço | U21: 1 | V21: 0 | W21: 7819760 | X21: 7819760 | Y21: 7805513 | AA21: 1854069.2 | AB21: 0 | AD21: DI | AE21: 100 | AF21: 0.094 | AG21: 252 | AH21: Percentual variavel, periodos uniformes, sobre valor remanescente
A22: 21ª Série - Premoaço | B22: Resgatada Antecipadamente | C22: 1 | D22: CRI | E22: 17J0883403 | F22: 21 | G22: Oliveira Trust | H22: 43039 | I22: 47467 | J22: 43220 | K22: 43273 | L22: CVM 476 | O22: BTS, Contrato de Cessāo Aluguel | P22: Nexus e BoticárioPrev | Q22: LOGOS COMPANHIA SECURITIZADORA S/A | R22: PENTAGONO DTVM SA | S22: CM Capital Markets | T22: Premoaço | U22: 1 | W22: 3500000 | X22: =W22*U22 -> 3500000 | Y22: 3500000 | AD22: CDI | AE22: 100 | AF22: 0.0525 | AG22: 252 | AH22: Percentual variavel, periodos uniformes, sobre valor remanescente
A23: 22ª Série - Rodobens | B23: Ativo | C23: 1 | D23: CRI | E23: 17L0911027 | F23: 22 | G23: Oliveira Trust | H23: 43095 | I23: 47832 | J23: 43278 | L23: CVM 476 | N23: BRLGOSCRI0U5 | O23: Cessāo Definitiva, CCI | P23: Nexus | Q23: LOGOS COMPANHIA SECURITIZADORA S/A | R23: PENTAGONO DTVM SA | T23: Rodobens e Paysage | U23: 1 | V23: 0 | W23: 6996891 | X23: 6996891 | Y23: 6996891 | AA23: 5429079.2 | AB23: 0 | AD23: IGP-M | AF23: 0.084 | AG23: 365 | AH23: Percentual variavel, periodos uniformes, sobre valor remanescente
A24: 23ª e 24ª Séries - Mascor | B24: Resgatada Antecipadamente | C24: 1 | D24: CRI | E24: 18E0828391 | F24: 23 | G24: Oliveira Trust | H24: 43238 | I24: 44941 | K24: 44012 | L24: CVM 476 | O24: Cessāo Fiduciária | P24: Nexus e BoticárioPrev | Q24: LOGOS COMPANHIA SECURITIZADORA S/A | R24: PENTAGONO DTVM SA | S24: CM Capital Markets | T24: Mascor Imóveis | U24: 1 | W24: 40000000 | X24: =W24*U24 -> 40000000 | AD24: IGP-M | AF24: 0.085 | AG24: 360 | AH24: Percentual variavel, periodos uniformes, sobre valor remanescente
A25: 23ª e 24ª Séries - Mascor | B25: Resgatada Antecipadamente | C25: 1 | D25: CRI | E25: 18E0828589 | F25: 24 | G25: Oliveira Trust | H25: 43238 | I25: 45580 | K25: 44012 | L25: CVM 476 | O25: Cessāo Fiduciária | P25: Nexus e BoticárioPrev | Q25: LOGOS COMPANHIA SECURITIZADORA S/A | R25: PENTAGONO DTVM SA | S25: CM Capital Markets | T25: Mascor Imóveis | U25: 1 | W25: 10000000 | X25: =W25*U25 -> 10000000 | AD25: IGP-M | AF25: 0.1452 | AG25: 360 | AH25: Percentual variavel, periodos uniformes, sobre valor remanescente
A26: 25ª e 26ª Séries - Life | B26: Resgatada Antecipadamente | C26: 1 | D26: CRI | E26: 19C0026866 | F26: 25 | G26: Oliveira Trust | H26: 43525 | I26: 48415 | K26: 44215 | L26: CVM 476 | O26: Cessāo Fiduciária, AF Quotas, AF Açōes | P26: Nexus e BoticárioPrev | Q26: LOGOS COMPANHIA SECURITIZADORA S/A | R26: PENTAGONO DTVM SA | S26: CM Capital Markets | T26: Life | U26: 1 | W26: 40000000 | X26: =W26*U26 -> 40000000 | AD26: IPCA | AF26: 0.085 | AG26: 360 | AH26: Percentual variavel, periodos uniformes, sobre valor remanescente
A27: 25ª e 26ª Séries - Life | B27: Resgatada Antecipadamente | C27: 1 | D27: CRI | E27: 19C0026867 | F27: 26 | G27: Oliveira Trust | H27: 43525 | I27: 48964 | K27: 44215 | L27: CVM 476 | O27: Cessāo Fiduciária, AF Quotas, AF Açōes | P27: Nexus e BoticárioPrev | Q27: LOGOS COMPANHIA SECURITIZADORA S/A | R27: PENTAGONO DTVM SA | S27: CM Capital Markets | T27: Life | U27: 1 | W27: 10000000 | X27: =W27*U27 -> 10000000 | AD27: IPCA | AF27: 0.168 | AG27: 360 | AH27: Percentual variavel, periodos uniformes, sobre valor remanescente
A28: 27ª, 28ª Séries - Paysage | B28: Ativo | C28: 1 | D28: CRI | E28: 19I0151853 | F28: 27 | G28: Oliveira Trust | H28: 43718 | I28: 47776 | J28: 43901 | L28: CVM 476 | N28: BRLGOSCRI0X9 | O28: Cessāo Fiduciária, AF Quotas, AF Açōes | P28: PH | Q28: LOGOS COMPANHIA SECURITIZADORA S/A | R28: PENTAGONO DTVM SA | T28: Paysage | U28: 1 | V28: 0 | W28: 11040000 | X28: 11040000 | Y28: 11010010 | AA28: 4866328.1 | AB28: =5336.36+1952.49+1116.9 -> 8405.75 | AC28: =66.27+1586+226.16 -> 1878.43 | AD28: IPCA | AF28: 0.085 | AG28: 360 | AH28: Percentual variavel, periodos uniformes, sobre valor remanescente
A29: 27ª, 28ª Séries - Paysage | B29: Ativo | C29: 1 | D29: CRI | E29: 19I0151856 | F29: 28 | G29: Oliveira Trust | H29: 43718 | I29: 48750 | J29: 43901 | L29: CVM 476 | N29: BRLGOSCRI0Y7 | O29: Cessāo Fiduciária, AF Quotas, AF Açōes | P29: PH | Q29: LOGOS COMPANHIA SECURITIZADORA S/A | R29: PENTAGONO DTVM SA | T29: Paysage | U29: 1 | V29: 0 | W29: 2760000 | X29: 2760000 | Y29: 2748117 | AA29: 1861380.6 | AB29: 0 | AD29: IPCA | AF29: 0.149 | AG29: 360 | AH29: Percentual variavel, periodos uniformes, sobre valor remanescente
A30: 29ª e 30ª Séries - Tecnobens | B30: Ativo | C30: 1 | D30: CRI | E30: 19I0301816 | F30: 29 | G30: Oliveira Trust | H30: 43728 | I30: 44824 | J30: 43910 | L30: CVM 476 | N30: BRLGOSCRI0K6 | O30: Cessāo Fiduciária, AF Quotas, AF Açōes | P30: Nexus e BoticárioPrev | Q30: LOGOS COMPANHIA SECURITIZADORA S/A | R30: PENTAGONO DTVM SA | T30: Tecnobens | U30: 1 | V30: 0 | W30: 34000000 | X30: 34000000 | Y30: 32631725 | Z30: ENVIAR AGT B3 | AA30: 28719743 | AB30: 11768.04 | AC30: 817.74 | AD30: IPCA | AF30: 0.07 | AG30: 360 | AH30: Percentual variavel, periodos uniformes, sobre valor remanescente
A31: 29ª e 30ª Séries - Tecnobens | B31: Ativo | C31: 1 | D31: CRI | E31: 19I0301867 | F31: 30 | G31: Oliveira Trust | H31: 43728 | I31: 44824 | J31: 43910 | L31: CVM 476 | N31: BRLGOSCRI0L4 | O31: Cessāo Fiduciária, AF Quotas, AF Açōes | P31: Nexus e BoticárioPrev | Q31: LOGOS COMPANHIA SECURITIZADORA S/A | R31: PENTAGONO DTVM SA | T31: Tecnobens | U31: 1 | V31: 0 | W31: 6000000 | X31: 6000000 | Y31: 5172958 | Z31: ENVIAR AGT B3 | AA31: 6341737.9 | AB31: 0 | AD31: IPCA | AF31: 0.391 | AG31: 360 | AH31: Percentual variavel, periodos uniformes, sobre valor remanescente
A32: 31ª e 32ª Séries - DJR | B32: Ativo | C32: 1 | D32: CRI | E32: 20C0937823 | F32: 31 | G32: Vortx | H32: 43906 | I32: 48908 | L32: CVM 476 | N32: BRLGOSCRI0N0 | O32: Debêntures | P32: Nexus e BoticárioPrev | Q32: LOGOS COMPANHIA SECURITIZADORA S/A | R32: H. Commcor | T32: DJR Participações S.A. | U32: 1 | V32: 0 | W32: 80000000 | X32: 80000000 | Y32: 39334942 | Z32: CANCELAR CRIS | AA32: 63882374 | AB32: 0 | AD32: IPCA | AF32: 0.07 | AG32: 360 | AH32: Percentual variavel, periodos uniformes, sobre valor remanescente
A33: 31ª e 32ª Séries - DJR | B33: Ativo | C33: 1 | D33: CRI | E33: 20C0937926 | F33: 32 | G33: Vortx | H33: 43906 | I33: 49334 | L33: CVM 476 | N33: BRLGOSCRI0Z4 | O33: Debêntures | P33: Nexus e BoticárioPrev | Q33: LOGOS COMPANHIA SECURITIZADORA S/A | R33: H. Commcor | T33: DJR Participações S.A. | U33: 1 | V33: 0 | W33: 20000000 | X33: 20000000 | Y33: 9801433 | AA33: 19178089 | AB33: 0 | AD33: IPCA | AF33: 0.11 | AG33: 360 | AH33: Percentual variavel, periodos uniformes, sobre valor remanescente
A34: 33ª e 34ª Séries - Paysage | B34: Ativo | C34: 1 | D34: CRI | E34: 20F0849615 | F34: 33 | G34: Oliveira Trust | H34: 44012 | I34: 47107 | L34: CVM 476 | N34: BRLGOSCRI0Z4 | O34: Cessāo Conta Bancária | P34: PH | Q34: LOGOS COMPANHIA SECURITIZADORA S/A | R34: PENTAGONO DTVM SA | T34: Paysage | U34: 1 | V34: 0 | W34: 16000000 | X34: 16000000 | Y34: 15005117 | AA34: 15406810 | AB34: 8109.39 | AD34: IPCA | AF34: 0.09 | AG34: 360 | AH34: Percentual variavel, periodos uniformes, sobre valor remanescente
A35: 33ª e 34ª Séries - Paysage | B35: Resgatada Antecipadamente | C35: 1 | D35: CRI | E35: 20F0849616 | F35: 34 | G35: Oliveira Trust | H35: 44012 | I35: 47623 | K35: 44277 | L35: CVM 476 | O35: Cessāo Conta Bancária | P35: PH | Q35: LOGOS COMPANHIA SECURITIZADORA S/A | R35: PENTAGONO DTVM SA | S35: CM Capital Markets | T35: Paysage | U35: 1 | W35: 4000000 | X35: =W35*U35 -> 4000000 | Y35: 963999 | Z35: Solicitar o cancelamento na B3 | AD35: IPCA | AF35: 0.1388 | AG35: 360 | AH35: Percentual variavel, periodos uniformes, sobre valor remanescente
A36: 35ª e 36ª Séries - Mascor | B36: Resgatada Antecipadamente | C36: 1 | D36: CRI | E36: 20F0784454 | F36: 35 | G36: Oliveira Trust | H36: 44007 | I36: 45797 | K36: 45586 | L36: CVM 476 | O36: Cessāo Fiduciária | P36: Nexus e BoticárioPrev | Q36: LOGOS COMPANHIA SECURITIZADORA S/A | R36: PENTAGONO DTVM SA | S36: LOGOS COMPANHIA SECURITIZADORA S/A | T36: Mascor Imóveis | U36: 1 | W36: 85000000 | X36: =W36*U36 -> 85000000 | Y36: 63750000 | Z36: Solicitar o cancelamento na B3 | AD36: IGP-M | AF36: 0.065 | AG36: 360 | AH36: Percentual variavel, periodos uniformes, sobre valor remanescente
A37: 35ª e 36ª Séries - Mascor | B37: Resgatada Antecipadamente | C37: 1 | D37: CRI | E37: 20F0784574 | F37: 36 | G37: Oliveira Trust | H37: 44007 | I37: 46162 | K37: 45586 | L37: CVM 476 | O37: Cessāo Fiduciária | P37: Nexus e BoticárioPrev | Q37: LOGOS COMPANHIA SECURITIZADORA S/A | R37: PENTAGONO DTVM SA | S37: LOGOS COMPANHIA SECURITIZADORA S/A | T37: Mascor Imóveis | U37: 1 | W37: 15000000 | X37: =W37*U37 -> 15000000 | Y37: 11250000 | Z37: Solicitar o cancelamento na B3 | AD37: IGP-M | AF37: 0.1338 | AG37: 360 | AH37: Percentual variavel, periodos uniformes, sobre valor remanescente
A38: 37ª Séries - Tecnobens | B38: Ativo | C38: 1 | D38: CRI | E38: 20K0609818 | F38: 37 | G38: Oliveira Trust | H38: 44151 | I38: 45250 | L38: CVM 476 | N38: BRLGOSCRI0R1 | O38: Cessāo Fiduciária, AF Quotas, AF Açōes | P38: Nexus, BoticárioPrev e PH | Q38: LOGOS COMPANHIA SECURITIZADORA S/A | R38: PENTAGONO DTVM SA | T38: Tecnobens | U38: 1 | V38: 0 | W38: 13000000 | X38: 13000000 | Y38: 10302019 | AA38: 10492164 | AB38: 0 | AD38: IPCA | AF38: 0.1275 | AG38: 360 | AH38: Percentual variavel, periodos uniformes, sobre valor remanescente
A39: 38ª, 39ª e 47ª Séries - CiaTC | B39: Ativo | C39: 1 | D39: CRA | E39: CRA020003VG | F39: 38 | G39: Vortx | H39: 44180 | I39: 46381 | L39: CVM 476 | N39: BRLGOSCRI110 | O39: Debêntures | P39: Nexus e Grupo CiaTC | Q39: LOGOS COMPANHIA SECURITIZADORA S/A | R39: H. Commcor | T39: Ciatc | U39: 1 | V39: 0 | W39: 10000000 | X39: 10000000 | Y39: 6790542 | AA39: 4381427 | AB39: =90000/12 -> 7500 | AD39: IPCA | AF39: 0.055 | AG39: 360 | AH39: Percentual variavel, periodos uniformes, sobre valor remanescente
A40: 38ª, 39ª e 47ª Séries - CiaTC | B40: Ativo | C40: 1 | D40: CRA | E40: CRA020003VH | F40: 39 | G40: Vortx | H40: 44180 | I40: 46381 | L40: CVM 476 | N40: BRLGOSCRI128 | O40: Debêntures | P40: Nexus e Grupo CiaTC | Q40: LOGOS COMPANHIA SECURITIZADORA S/A | R40: H. Commcor | T40: Ciatc | U40: 1 | V40: 0 | W40: 20000000 | X40: 20000000 | Y40: 19400435 | AA40: 12534084 | AB40: 0 | AD40: IPCA | AF40: 0.06 | AG40: 360 | AH40: Percentual variavel, periodos uniformes, sobre valor remanescente
...

Sheet Prestadores de Serviço
B2: egoria | C2: Campo | D2: Tipo de Dado | E2: Obrigatório? | F2: Exemplo
B3: Dados Cadastrais | C3: Razão Social | D3: Texto | E3: Sim | F3: XYZ Indústria Ltda.
C4: Nome Fantasia | D4: Texto | E4: Não | F4: XYZ Soluções
C5: CNPJ | D5: Número (14 dígitos) | E5: Sim | F5: 12.345.678/0001-99
C6: Inscrição Estadual (IE) | D6: Texto | E6: Depende* | F6: 123456789112
C7: Inscrição Municipal (IM) | D7: Texto | E7: Depende* | F7: 987654
C8: Data de Abertura | D8: Data | E8: Sim | F8: 40252
C9: CNAE Principal | D9: Número (7 dígitos) | E9: Sim | F9: 2829-1/00
B10: Dados Fiscais | C10: Regime Tributário | D10: Lista (Simples, Lucro Real/Presumido) | E10: Sim | F10: Simples Nacional
C11: Optante pelo SIMPLES? | D11: Sim/Não | E11: Sim | F11: Sim
C12: Substituição Tributária? | D12: Sim/Não | E12: Sim | F12: Não
C13: Certificado Digital (e-CNPJ)? | D13: Sim/Não | E13: Não | F13: Sim
B14: Endereço | C14: Logradouro | D14: Texto | E14: Sim | F14: Av. das Indústrias
C15: Número | D15: Texto/Número | E15: Sim | F15: 1500
C16: Complemento | D16: Texto | E16: Não | F16: Bloco B, Sala 301
C17: Bairro | D17: Texto | E17: Sim | F17: Industrial
C18: Cidade | D18: Texto | E18: Sim | F18: São Paulo
C19: UF | D19: Lista (BR) | E19: Sim | F19: SP
C20: CEP | D20: Número (8 dígitos) | E20: Sim | F20: 01234-567
B21: Contato | C21: Telefone Principal | D21: Texto | E21: Sim | F21: (11) 98765-4321
C22: E-mail | D22: E-mail | E22: Sim | F22: contato@xyz.com.br
C23: Nome do Responsável | D23: Texto | E23: Sim | F23: João Silva
C24: Cargo do Responsável | D24: Texto | E24: Não | F24: Gerente Comercial
B25: Dados Bancários | C25: Banco | D25: Texto | E25: Não | F25: Banco do Brasil
C26: Agência | D26: Número | E26: Não | F26: 1234
C27: Conta Corrente | D27: Número/Texto | E27: Não | F27: 56789-0
C28: Tipo de Conta (Corrente/Poupança) | D28: Lista | E28: Não | F28: Corrente
C29: Pix (Chave) | D29: Texto | E29: Não | F29: 12.345.678/0001-99 (CNPJ)
B30: Informações Adicionais | C30: Produtos/Serviços Fornecidos | D30: Texto | E30: Não | F30: Peças automotivas
C31: Prazo de Entrega Médio | D31: Texto | E31: Não | F31: 15 dias úteis
C32: Condições de Pagamento | D32: Texto | E32: Não | F32: 30 dias após fatura
C33: Observações | D33: Texto Livre | E33: Não | F33: Fornecedor preferencial desde 2018

Sheet Investidores
A2: Dados Pessoais
A3: Código do Cliente | B3: Nome do Cliente | C3: CPF | D3: Tipo de documento | E3: Número do documento | F3: Data de emissão | G3: Órgão Emissor | H3: UF do emissor | I3: Data de Nascimento | J3: Sexo | K3: Local de Nascimento | L3: UF (Nascimento) | M3: País de Nascimento | N3: País de Residência Fiscal | O3: NIF | P3: Nome do Pai | Q3: Nome da Mãe | R3: Estado Civil | S3: Nome do Cônjuge | T3: Endereço | U3: Número | V3: Complemento | W3: Bairro | X3: Cidade | Y3: UF | Z3: CEP | AA3: Caixa Postal | AB3: Skype | AC3: Telefone Residencial | AD3: Celular | AE3: E-mail | AF3: Ocupação Principal | AG3: Cargo/Função | AH3: Empresa que Trabalha | AI3: Endereço Comercial | AJ3: Número | AK3: Complemento | AL3: Bairro | AM3: Cidade | AN3: UF | AO3: CEP | AP3: Caixa Postal | AQ3: Skype | AR3: Telefone Comercial | AS3: Celular | AT3: E-mail | AU3: Endereço para correspondência | AV3: Banco | AW3: Agência | AX3: Número da Conta | AY3: Co-Titular | AZ3: CPF do Co-Titular | BA3: Bens Imóveis (Tipo) | BB3: Endereço do Imóvel | BC3: Cidade | BD3: UF | BE3: Valor | BF3: Outros Bens (Tipo) | BG3: Descrição | BH3: Valor | BI3: Ativos Financeiros | BJ3: Descrição | BK3: Valor | BL3: Salário/Pró Labore | BM3: Outros Rendimentos | BN3: Valor Total (Patrimônio) | BO3: Opera por conta própria? | BP3: Pessoa Vinculada à Securitizadora? | BQ3: Pessoa Politicamente Exposta? | BR3: Autoriza transmissão por procurador? | BS3: Forma de transmissão de ordens: Verbal ( ) / Escrito ( ) | BT3: Permite carteira própria como contraparte? (Concordo/Não Concordo/Consulta) | BU3: É US Person? | BV3: País de nascimento/cidadania é EUA? | BW3: Possui Green Card? | BX3: Residência fiscal nos EUA? | BY3: Americano Naturalizado? | BZ3: Pai/Mãe estrangeiros? (Se sim, país) | CA3: Assinatura do Cliente | CB3: Data_assinatura_cad_inv | CC3: Nome do Responsável (Securitizadora) | CD3: Assinatura do Responsável | CE3: Data_conferencia_cad_inv | CF3: Banco_custodiante | CG3: Conta_banco_custodiante

Sheet Distribuiçōes
A1: Data | B1: Tipo ativo | C1: Codigo_if | D1: Preço Unitário | E1: Quantidades | F1: Valor total | G1: Escriturador | H1: Conta Escriturador | I1: Coordenador Lider | J1: Conta Emissor | K1: Conta Coordenador Líder | L1: Investidor

Sheet Resumo
A1: Operação | B1: Saldo Devedor | C1: Saldo Devedor | D1: Gestão | E1: Servicer | F1: TOTAL
A2: 4ª Série - Paysage | B2: =VLOOKUP(A2,'Características de CRI - LOGOS'!$A$5:$P$62,7,0) -> Oliveira Trust | C2: =SUMIF('Características de CRI - LOGOS'!$A$5:$A$62,Resumo!A2,'Características de CRI - LOGOS'!$AA$5:$AA$69) -> 2658663 | D2: 10284.84 | E2: 902.91749 | F2: =SUM(D2:E2) -> 11187.757
A3: 12ª Série - Paysage | B3: =VLOOKUP(A3,'Características de CRI - LOGOS'!$A$5:$P$62,7,0) -> #N/A | C3: =SUMIF('Características de CRI - LOGOS'!$A$5:$A$62,Resumo!A3,'Características de CRI - LOGOS'!$AA$5:$AA$69) -> 0 | D3: 19068.95 | E3: 2081.168 | F3: =SUM(D3:E3) -> 21150.118
A4: 18ª, 19ª, 20ª Séries - Premoaço | B4: =VLOOKUP(A4,'Características de CRI - LOGOS'!$A$5:$P$62,7,0) -> Oliveira Trust | C4: =SUMIF('Características de CRI - LOGOS'!$A$5:$A$62,Resumo!A4,'Características de CRI - LOGOS'!$AA$5:$AA$69) -> 5723598.6 | D4: 11388.81 | F4: =SUM(D4:E4) -> 11388.81
A5: 22ª Série - Rodobens | B5: =VLOOKUP(A5,'Características de CRI - LOGOS'!$A$5:$P$62,7,0) -> Oliveira Trust | C5: =SUMIF('Características de CRI - LOGOS'!$A$5:$A$62,Resumo!A5,'Características de CRI - LOGOS'!$AA$5:$AA$69) -> 5429079.2 | D5: 0 | F5: =SUM(D5:E5) -> 0
A6: 27ª, 28ª Séries - Paysage | B6: =VLOOKUP(A6,'Características de CRI - LOGOS'!$A$5:$P$62,7,0) -> Oliveira Trust | C6: =SUMIF('Características de CRI - LOGOS'!$A$5:$A$62,Resumo!A6,'Características de CRI - LOGOS'!$AA$5:$AA$69) -> 6727708.7 | D6: =5441.29+1990.88+1138.36 -> 8570.53 | E6: 2106.0736 | F6: =SUM(D6:E6) -> 10676.604
A7: 29ª, 30ª e 37ª Séries - Tecnobens | B7: =VLOOKUP(A7,'Características de CRI - LOGOS'!$A$5:$P$62,7,0) -> #N/A | C7: =SUMIF('Características de CRI - LOGOS'!$A$5:$A$62,Resumo!A7,'Características de CRI - LOGOS'!$AA$5:$AA$69) -> 0 | D7: 11700.36 | E7: 813.06 | F7: =SUM(D7:E7) -> 12513.42
A8: 31ª, 32ª e 46ª Séries - DJR | B8: =VLOOKUP(A8,'Características de CRI - LOGOS'!$A$5:$P$62,7,0) -> #N/A | C8: =SUMIF('Características de CRI - LOGOS'!$A$5:$A$62,Resumo!A8,'Características de CRI - LOGOS'!$AA$5:$AA$69) -> 0 | D8: 0 | F8: =SUM(D8:E8) -> 0
A9: 33ª Série - Paysage | B9: =VLOOKUP(A9,'Características de CRI - LOGOS'!$A$5:$P$62,7,0) -> #N/A | C9: =SUMIF('Características de CRI - LOGOS'!$A$5:$A$62,Resumo!A9,'Características de CRI - LOGOS'!$AA$5:$AA$69) -> 0 | D9: 8333.46 | F9: =SUM(D9:E9) -> 8333.46
A10: 35ª e 36ª - Mascor | B10: =VLOOKUP(A10,'Características de CRI - LOGOS'!$A$5:$P$62,7,0) -> #N/A | C10: =SUMIF('Características de CRI - LOGOS'!$A$5:$A$62,Resumo!A10,'Características de CRI - LOGOS'!$AA$5:$AA$69) -> 0 | D10: 17011.59 | F10: =SUM(D10:E10) -> 17011.59
A11: 38ª, 39ª e 47ª Séries - CiaTC | B11: =VLOOKUP(A11,'Características de CRI - LOGOS'!$A$5:$P$62,7,0) -> Vortx | C11: =SUMIF('Características de CRI - LOGOS'!$A$5:$A$62,Resumo!A11,'Características de CRI - LOGOS'!$AA$5:$AA$69) -> 29531044 | D11: 75000 | F11: =SUM(D11:E11) -> 75000
A12: 40ª, 41ª, 42ª, 48ª e 49ª Séries - Life | B12: =VLOOKUP(A12,'Características de CRI - LOGOS'!$A$5:$P$62,7,0) -> 0 | C12: =SUMIF('Características de CRI - LOGOS'!$A$5:$A$62,Resumo!A12,'Características de CRI - LOGOS'!$AA$5:$AA$69) -> 1.5773334e+08 | D12: 16456.67 | F12: =SUM(D12:E12) -> 16456.67
A13: 45ª Série - Paysage | B13: =VLOOKUP(A13,'Características de CRI - LOGOS'!$A$5:$P$62,7,0) -> Oliveira Trust | C13: =SUMIF('Características de CRI - LOGOS'!$A$5:$A$62,Resumo!A13,'Características de CRI - LOGOS'!$AA$5:$AA$69) -> 2039779.2 | D13: 6702 | F13: =SUM(D13:E13) -> 6702
A14: 1ª a 12ª Séries - Fundo Artemis | B14: =VLOOKUP(A14,'Características de CRI - LOGOS'!$A$5:$P$62,7,0) -> #N/A | C14: =SUMIF('Características de CRI - LOGOS'!$A$5:$A$62,Resumo!A14,'Características de CRI - LOGOS'!$AA$5:$AA$69) -> 0 | D14: 5500 | F14: =SUM(D14:E14) -> 5500
C15: =SUM(C2:C14) -> 2.0984321e+08 | D15: =SUM(D2:D14) -> 190017.21 | E15: =SUM(E2:E14) -> 5903.2191 | F15: =SUM(F2:F14) -> 195920.43
