Workbook

Sheet Características de CRI - LOGOS
A1: Emissão | B1: Papel | C1: Código IF | D1: Série | E1: Escriturador | F1: Data de Emiss„o | G1: Tipo da Oferta | H1: Data de Integralizaçāo | I1: ISIN | J1: Estrutura/ | K1: Investidor | L1: Emissor | M1: Agente Fiduci·rio | N1: Escriturador | O1: Coordenador Líder | P1: Cedente | Q1: PU Emissāo | R1: Ágio | S1: Qtd Emitida | T1: Volume Emiss„o | U1: Qtd Integralizada | V1: Observaçāo | W1: Saldo Devedor | X1: Gestão | Y1: Servicing | Z1: Data de Emiss„o | AA1: Data de Vencimento | AB1: Data Final de DistribuiÁ„o | AC1: Indexador | AD1: % Taxa Flutuante | AE1: Taxa de Juros PrÈ/Spread | AF1: Pagamento de Juros | AG1: AmortizaÁ„o
A2: 1 | B2: CRI | C2: 15L0542115 | D2: 4 | E2: Oliveira Trust | F2: 42348 | G2: CVM 476 | I2: BRLGOSCRI0T7 | J2: Cessāo Fiduciária | K2: PH | L2: LOGOS COMPANHIA SECURITIZADORA S/A | M2: PENTAGONO DTVM SA | P2: Paysage | Q2: 1000000 | R2: 0 | S2: 5 | T2: 5000000 | U2: 5 | W2: 2658663 | X2: 9652.32 | Y2: 837.68 | Z2: 42348 | AA2: 47684 | AB2: 42539 | AC2: IPCA | AE2: 0.11 | AF2: 360 | AG2: Percentual variavel, periodos uniformes, sobre valor remanescente
A3: 1 | B3: CRI | C3: 18F0732035 | D3: 18 | E3: Oliveira Trust | F3: 43262 | G3: CVM 476 | I3: BRLGOSCRI0H2 | J3: BTS, Contrato de Cessāo Aluguel | K3: Nexus e BoticárioPrev | L3: LOGOS COMPANHIA SECURITIZADORA S/A | M3: PENTAGONO DTVM AS | P3: Premoaço | Q3: 1 | R3: 0 | S3: 7200000 | T3: 7200000 | U3: 7200000 | W3: 3755938.8 | X3: 0 | Z3: 43262 | AA3: 47983 | AB3: 43453 | AC3: DI | AD3: 100 | AE3: 0.0525 | AF3: 252 | AG3: Percentual variavel, periodos uniformes, sobre valor remanescente
A4: 1 | B4: CRI | C4: 17G1668350 | D4: 19 | E4: Oliveira Trust | F4: 42941 | G4: CVM 476 | I4: BRLGOSCRI0A7 | J4: BTS, Contrato de Cessāo Aluguel | K4: Nexus e BoticárioPrev | L4: LOGOS COMPANHIA SECURITIZADORA S/A | M4: PENTAGONO DTVM SA | P4: Premoaço | Q4: 1 | R4: 0 | S4: 18246106 | T4: 18246106 | U4: 0 | W4: 113590.63 | X4: 10761.36 | Z4: 42941 | AA4: 45641 | AB4: 43126 | AC4: DI | AD4: 100 | AE4: 0.015 | AF4: 252 | AG4: Percentual variavel, periodos uniformes, sobre valor remanescente
A5: 1 | B5: CRI | C5: 17G1668137 | D5: 20 | E5: Oliveira Trust | F5: 42941 | G5: CVM 476 | I5: BRLGOSCRI0B5 | J5: BTS, Contrato de Cessāo Aluguel | K5: Nexus e BoticárioPrev | L5: LOGOS COMPANHIA SECURITIZADORA S/A | M5: PENTAGONO DTVM SA | P5: Premoaço | Q5: 1 | R5: 0 | S5: 7819760 | T5: 7819760 | U5: 7805513 | W5: 1854069.2 | X5: 0 | Z5: 42941 | AA5: 46188 | AB5: 43126 | AC5: DI | AD5: 100 | AE5: 0.094 | AF5: 252 | AG5: Percentual variavel, periodos uniformes, sobre valor remanescente
A6: 1 | B6: CRI | C6: 17L0911027 | D6: 22 | E6: Oliveira Trust | F6: 43095 | G6: CVM 476 | I6: BRLGOSCRI0U5 | J6: Cessāo Definitiva, CCI | K6: Nexus | L6: LOGOS COMPANHIA SECURITIZADORA S/A | M6: PENTAGONO DTVM SA | P6: Rodobens e Paysage | Q6: 1 | R6: 0 | S6: 6996891 | T6: 6996891 | U6: 6996891 | W6: 5429079.2 | X6: 0 | Z6: 43095 | AA6: 47832 | AB6: 43278 | AC6: IGP-M | AE6: 0.084 | AF6: 365 | AG6: Percentual variavel, periodos uniformes, sobre valor remanescente
A7: 1 | B7: CRI | C7: 19I0151853 | D7: 27 | E7: Oliveira Trust | F7: 43718 | G7: CVM 476 | I7: BRLGOSCRI0X9 | J7: Cessāo Fiduciária, AF Quotas, AF Açōes | K7: PH | L7: LOGOS COMPANHIA SECURITIZADORA S/A | M7: PENTAGONO DTVM SA | P7: Paysage | Q7: 1 | R7: 0 | S7: 11040000 | T7: 11040000 | U7: 11010010 | W7: 4866328.1 | X7: =5336.36+1952.49+1116.9 -> 8405.75 | Y7: =66.27+1586+226.16 -> 1878.43 | Z7: 43718 | AA7: 47776 | AB7: 43901 | AC7: IPCA | AE7: 0.085 | AF7: 360 | AG7: Percentual variavel, periodos uniformes, sobre valor remanescente
A8: 1 | B8: CRI | C8: 19I0151856 | D8: 28 | E8: Oliveira Trust | F8: 43718 | G8: CVM 476 | I8: BRLGOSCRI0Y7 | J8: Cessāo Fiduciária, AF Quotas, AF Açōes | K8: PH | L8: LOGOS COMPANHIA SECURITIZADORA S/A | M8: PENTAGONO DTVM SA | P8: Paysage | Q8: 1 | R8: 0 | S8: 2760000 | T8: 2760000 | U8: 2748117 | W8: 1861380.6 | X8: 0 | Z8: 43718 | AA8: 48750 | AB8: 43901 | AC8: IPCA | AE8: 0.149 | AF8: 360 | AG8: Percentual variavel, periodos uniformes, sobre valor remanescente
A9: 1 | B9: CRI | C9: 19I0301816 | D9: 29 | E9: Oliveira Trust | F9: 43728 | G9: CVM 476 | I9: BRLGOSCRI0K6 | J9: Cessāo Fiduciária, AF Quotas, AF Açōes | K9: Nexus e BoticárioPrev | L9: LOGOS COMPANHIA SECURITIZADORA S/A | M9: PENTAGONO DTVM SA | P9: Tecnobens | Q9: 1 | R9: 0 | S9: 34000000 | T9: 34000000 | U9: 32631725 | V9: ENVIAR AGT B3 | W9: 28719743 | X9: 11768.04 | Y9: 817.74 | Z9: 43728 | AA9: 44824 | AB9: 43910 | AC9: IPCA | AE9: 0.07 | AF9: 360 | AG9: Percentual variavel, periodos uniformes, sobre valor remanescente
A10: 1 | B10: CRI | C10: 19I0301867 | D10: 30 | E10: Oliveira Trust | F10: 43728 | G10: CVM 476 | I10: BRLGOSCRI0L4 | J10: Cessāo Fiduciária, AF Quotas, AF Açōes | K10: Nexus e BoticárioPrev | L10: LOGOS COMPANHIA SECURITIZADORA S/A | M10: PENTAGONO DTVM SA | P10: Tecnobens | Q10: 1 | R10: 0 | S10: 6000000 | T10: 6000000 | U10: 5172958 | V10: ENVIAR AGT B3 | W10: 6341737.9 | X10: 0 | Z10: 43728 | AA10: 44824 | AB10: 43910 | AC10: IPCA | AE10: 0.391 | AF10: 360 | AG10: Percentual variavel, periodos uniformes, sobre valor remanescente
A11: 1 | B11: CRI | C11: 20C0937823 | D11: 31 | E11: Vortx | F11: 43906 | G11: CVM 476 | I11: BRLGOSCRI0N0 | J11: Debêntures | K11: Nexus e BoticárioPrev | L11: LOGOS COMPANHIA SECURITIZADORA S/A | M11: H. Commcor | P11: DJR Participações S.A. | Q11: 1 | R11: 0 | S11: 80000000 | T11: 80000000 | U11: 39334942 | V11: CANCELAR CRIS | W11: 63882374 | X11: 0 | Z11: 43906 | AA11: 48908 | AC11: IPCA | AE11: 0.07 | AF11: 360 | AG11: Percentual variavel, periodos uniformes, sobre valor remanescente
A12: 1 | B12: CRI | C12: 20C0937926 | D12: 32 | E12: Vortx | F12: 43906 | G12: CVM 476 | I12: BRLGOSCRI0Z4 | J12: Debêntures | K12: Nexus e BoticárioPrev | L12: LOGOS COMPANHIA SECURITIZADORA S/A | M12: H. Commcor | P12: DJR Participações S.A. | Q12: 1 | R12: 0 | S12: 20000000 | T12: 20000000 | U12: 9801433 | W12: 19178089 | X12: 0 | Z12: 43906 | AA12: 49334 | AC12: IPCA | AE12: 0.11 | AF12: 360 | AG12: Percentual variavel, periodos uniformes, sobre valor remanescente
A13: 1 | B13: CRI | C13: 20F0849615 | D13: 33 | E13: Oliveira Trust | F13: 44012 | G13: CVM 476 | I13: BRLGOSCRI0Z4 | J13: Cessāo Conta Bancária | K13: PH | L13: LOGOS COMPANHIA SECURITIZADORA S/A | M13: PENTAGONO DTVM SA | P13: Paysage | Q13: 1 | R13: 0 | S13: 16000000 | T13: 16000000 | U13: 15005117 | W13: 15406810 | X13: 8109.39 | Z13: 44012 | AA13: 47107 | AC13: IPCA | AE13: 0.09 | AF13: 360 | AG13: Percentual variavel, periodos uniformes, sobre valor remanescente
A14: 1 | B14: CRI | C14: 20K0609818 | D14: 37 | E14: Oliveira Trust | F14: 44151 | G14: CVM 476 | I14: BRLGOSCRI0R1 | J14: Cessāo Fiduciária, AF Quotas, AF Açōes | K14: Nexus, BoticárioPrev e PH | L14: LOGOS COMPANHIA SECURITIZADORA S/A | M14: PENTAGONO DTVM SA | P14: Tecnobens | Q14: 1 | R14: 0 | S14: 13000000 | T14: 13000000 | U14: 10302019 | W14: 10492164 | X14: 0 | Z14: 44151 | AA14: 45250 | AC14: IPCA | AE14: 0.1275 | AF14: 360 | AG14: Percentual variavel, periodos uniformes, sobre valor remanescente
A15: 1 | B15: CRA | C15: CRA020003VG | D15: 38 | E15: Vortx | F15: 44180 | G15: CVM 476 | I15: BRLGOSCRI110 | J15: Debêntures | K15: Nexus e Grupo CiaTC | L15: LOGOS COMPANHIA SECURITIZADORA S/A | M15: H. Commcor | P15: Ciatc | Q15: 1 | R15: 0 | S15: 10000000 | T15: 10000000 | U15: 6790542 | W15: 4381427 | X15: =90000/12 -> 7500 | Z15: 44180 | AA15: 46381 | AC15: IPCA | AE15: 0.055 | AF15: 360 | AG15: Percentual variavel, periodos uniformes, sobre valor remanescente
A16: 1 | B16: CRA | C16: CRA020003VH | D16: 39 | E16: Vortx | F16: 44180 | G16: CVM 476 | I16: BRLGOSCRI128 | J16: Debêntures | K16: Nexus e Grupo CiaTC | L16: LOGOS COMPANHIA SECURITIZADORA S/A | M16: H. Commcor | P16: Ciatc | Q16: 1 | R16: 0 | S16: 20000000 | T16: 20000000 | U16: 19400435 | W16: 12534084 | X16: 0 | Z16: 44180 | AA16: 46381 | AC16: IPCA | AE16: 0.06 | AF16: 360 | AG16: Percentual variavel, periodos uniformes, sobre valor remanescente
A17: 1 | B17: CRI | C17: 21A0618761 | D17: 40 | F17: 44210 | G17: CVM 476 | I17: BRLGOSCRI136 | J17: Debêntures | K17: Nexus e BoticárioPrev | L17: LOGOS COMPANHIA SECURITIZADORA S/A | M17: H. Commcor | P17: Life | Q17: 1 | R17: 0 | S17: 35000000 | T17: 35000000 | U17: 35000000 | W17: 41382629 | X17: 15444.59 | Z17: 44210 | AA17: 49663 | AC17: IPCA | AE17: 0.105 | AF17: 360 | AG17: Percentual variavel, periodos uniformes, sobre valor remanescente
A18: 1 | B18: CRI | C18: 21A0618769 | D18: 41 | F18: 44210 | G18: CVM 476 | I18: BRLGOSCRI144 | J18: Debêntures | K18: Nexus e BoticárioPrev | L18: LOGOS COMPANHIA SECURITIZADORA S/A | M18: H. Commcor | P18: Life | Q18: 1 | R18: 0 | S18: 66860907 | T18: 66860907 | U18: 65445547 | W18: 77380252 | X18: 0 | Z18: 44210 | AA18: 49663 | AC18: IPCA | AE18: 0.07 | AF18: 360 | AG18: Percentual variavel, periodos uniformes, sobre valor remanescente
A19: 1 | B19: CRI | C19: 21A0618771 | D19: 42 | F19: 44210 | G19: CVM 476 | I19: BRLGOSCRI151 | J19: Debêntures | K19: Nexus e BoticárioPrev | L19: LOGOS COMPANHIA SECURITIZADORA S/A | M19: H. Commcor | P19: Life | Q19: 1 | R19: 0 | S19: 11798984 | T19: 11798984 | U19: 11798984 | W19: 13080211 | X19: 0 | Z19: 44210 | AA19: 49663 | AC19: IPCA | AE19: 0.1734 | AF19: 360 | AG19: Percentual variavel, periodos uniformes, sobre valor remanescente
A20: 1 | B20: CRI | C20: 21H1083493 | D20: 45 | E20: Oliveira Trust | F20: 44469 | G20: CVM 476 | I20: BRLGOSCRI185 | J20: Cessāo Fiduciária, AF Quotas, AF Açōes | K20: PH | L20: LOGOS COMPANHIA SECURITIZADORA S/A | M20: GCD Partners | P20: Paysage | Q20: 1 | R20: 0 | S20: 20000000 | T20: 20000000 | U20: 20000000 | W20: 2039779.2 | X20: 6290.3 | Z20: 44469 | AA20: 48080 | AC20: IPCA | AE20: 0.095 | AF20: 360 | AG20: Percentual variavel, periodos uniformes, sobre valor remanescente
A21: 1 | B21: CRI | C21: 22F1187231 | D21: 46 | F21: 44739 | G21: CVM 476 | I21: BRLGOSCRI193 | J21: Debêntures | K21: Nexus | L21: LOGOS COMPANHIA SECURITIZADORA S/A | M21: H. Commcor | P21: DJR Participações S.A. | Q21: 1 | R21: 0 | S21: 100000000 | T21: 100000000 | U21: 24317016 | W21: 32474628 | X21: 0 | Z21: 44739 | AA21: 48908 | AC21: IPCA | AE21: 0.095 | AF21: 360 | AG21: Percentual variavel, periodos uniformes, sobre valor remanescente
A22: 1 | B22: CRA | C22: CRA023008SP | D22: 47 | F22: 45041 | G22: RCVM 60 | I22: BRLGOSCRA000 | J22: Debêntures | K22: Nexus e Grupo CiaTC | L22: LOGOS COMPANHIA SECURITIZADORA S/A | M22: H. Commcor | P22: Ciatc | Q22: 1 | R22: 0 | S22: 15000000 | T22: 15000000 | U22: 14745477 | W22: 12615533 | X22: 0 | Z22: 45041 | AA22: 46137 | AC22: IPCA | AE22: 0.085 | AF22: 360 | AG22: Percentual variavel, periodos uniformes, sobre valor remanescente
A23: 1 | B23: CRI | C23: 23L1537405 | D23: 48 | F23: 45267 | G23: RCVM 60 | I23: BRLGOSCRI1A5 | J23: Debêntures | K23: Nexus e BoticárioPrev | L23: LOGOS COMPANHIA SECURITIZADORA S/A | M23: H. Commcor | P23: Life | Q23: 1 | R23: 0 | S23: 102000000 | T23: 102000000 | U23: 21250000 | W23: 21250930 | X23: 0 | Z23: 45267 | AA23: 50729 | AC23: IPCA | AE23: 0.07 | AF23: 360 | AG23: Percentual variavel, periodos uniformes, sobre valor remanescente
A24: 1 | B24: CRI | C24: 23L1537490 | D24: 49 | F24: 45267 | G24: RCVM 60 | I24: BRLGOSCRI1B3 | J24: Debêntures | K24: Nexus e BoticárioPrev | L24: LOGOS COMPANHIA SECURITIZADORA S/A | M24: H. Commcor | P24: Life | Q24: 1 | R24: 0 | S24: 18000000 | T24: 18000000 | U24: 5212225 | W24: 4639316.4 | X24: 0 | Z24: 45267 | AA24: 50729 | AC24: IPCA | AE24: 0.22 | AF24: 360 | AG24: Percentual variavel, periodos uniformes, sobre valor remanescente
A25: 2 | B25: CRI | C25: 23L2859168 | D25: 1 | F25: 45279 | G25: RCVM 60 | I25: BRLGOSCRI1C1 | J25: CCI | K25: Fundo Artemis | L25: LOGOS COMPANHIA SECURITIZADORA S/A | M25: Vortx DTVM Ltda. | P25: Life | Q25: 1 | S25: 3853412 | T25: 3853412 | U25: 3853412 | W25: 3745267.1 | X25: 7000 | Z25: 45279 | AA25: 50734 | AC25: IPCA | AE25: 0.1193 | AF25: 252 | AG25: Percentual variavel, periodos uniformes, sobre valor remanescente
A26: 2 | B26: CRI | C26: 23L2884758 | D26: 2 | F26: 45279 | G26: RCVM 60 | I26: BRLGOSCRI1D9 | J26: CCI | K26: Fundo Artemis | L26: LOGOS COMPANHIA SECURITIZADORA S/A | M26: Vortx DTVM Ltda. | P26: Life | Q26: 1 | S26: 3471185 | T26: 3471185 | U26: 3471185 | W26: 3323130.5 | X26: 0 | Z26: 45280 | AA26: 50734 | AC26: IPCA | AE26: 0.1193 | AF26: 252 | AG26: Percentual variavel, periodos uniformes, sobre valor remanescente
A27: 2 | B27: CRI | C27: 23L2884760 | D27: 3 | F27: 45279 | G27: RCVM 60 | I27: BRLGOSCRI1E7 | J27: CCI | K27: Fundo Artemis | L27: LOGOS COMPANHIA SECURITIZADORA S/A | M27: Vortx DTVM Ltda. | P27: Life | Q27: 1 | S27: 3868594 | T27: 3868594 | U27: 3868594 | W27: 3683852.9 | X27: 0 | Z27: 45281 | AA27: 50734 | AC27: IPCA | AE27: 0.1193 | AF27: 252 | AG27: Percentual variavel, periodos uniformes, sobre valor remanescente
A28: 2 | B28: CRI | C28: 23L2884761 | D28: 4 | F28: 45279 | G28: RCVM 60 | I28: BRLGOSCRI1F4 | J28: CCI | K28: Fundo Artemis | L28: LOGOS COMPANHIA SECURITIZADORA S/A | M28: Vortx DTVM Ltda. | P28: Life | Q28: 1 | S28: 4099594 | T28: 4099594 | U28: 4099594 | W28: 3866270.6 | X28: 0 | Z28: 45282 | AA28: 50734 | AC28: IPCA | AE28: 0.1193 | AF28: 252 | AG28: Percentual variavel, periodos uniformes, sobre valor remanescente
A29: 2 | B29: CRI | C29: 23L2884762 | D29: 5 | F29: 45279 | G29: RCVM 60 | I29: BRLGOSCRI1G2 | J29: CCI | K29: Fundo Artemis | L29: LOGOS COMPANHIA SECURITIZADORA S/A | M29: Vortx DTVM Ltda. | P29: Life | Q29: 1 | S29: 3726870 | T29: 3726870 | U29: 3726870 | W29: 3304333 | X29: 0 | Z29: 45283 | AA29: 50734 | AC29: IPCA | AE29: 0.1193 | AF29: 252 | AG29: Percentual variavel, periodos uniformes, sobre valor remanescente
A30: 2 | B30: CRI | C30: 23L2884763 | D30: 6 | F30: 45279 | G30: RCVM 60 | I30: BRLGOSCRI1H0 | J30: CCI | K30: Fundo Artemis | L30: LOGOS COMPANHIA SECURITIZADORA S/A | M30: Vortx DTVM Ltda. | P30: Life | Q30: 1 | S30: 3882659 | T30: 3882659 | U30: 3882659 | W30: 3562291.6 | X30: 0 | Z30: 45284 | AA30: 50734 | AC30: IPCA | AE30: 0.1193 | AF30: 252 | AG30: Percentual variavel, periodos uniformes, sobre valor remanescente
A31: 2 | B31: CRI | C31: 24D3312860 | D31: 7 | F31: 45401 | G31: RCVM 60 | I31: BRLGOSCRI1I8 | J31: CCI | K31: Fundo Artemis | L31: LOGOS COMPANHIA SECURITIZADORA S/A | M31: Vortx DTVM Ltda. | P31: Life | Q31: 1 | S31: 4982038 | T31: 4982038 | U31: 4982038 | W31: 4816427.8 | X31: 0 | Z31: 45401 | AA31: 50854 | AC31: IPCA | AE31: 0.105 | AF31: 252 | AG31: Percentual variavel, periodos uniformes, sobre valor remanescente
A32: 2 | B32: CRI | C32: 24D3312914 | D32: 8 | F32: 45401 | G32: RCVM 60 | I32: BRLGOSCRI1J6 | J32: CCI | K32: Fundo Artemis | L32: LOGOS COMPANHIA SECURITIZADORA S/A | M32: Vortx DTVM Ltda. | P32: Life | Q32: 1 | S32: 4727722 | T32: 4727722 | U32: 4727722 | W32: 4493116.6 | X32: 0 | Z32: 45401 | AA32: 50854 | AC32: IPCA | AE32: 0.105 | AF32: 252 | AG32: Percentual variavel, periodos uniformes, sobre valor remanescente
A33: 2 | B33: CRI | C33: 24D3313010 | D33: 9 | F33: 45401 | G33: RCVM 60 | I33: BRLGOSCRI1K4 | J33: CCI | K33: Fundo Artemis | L33: LOGOS COMPANHIA SECURITIZADORA S/A | M33: Vortx DTVM Ltda. | P33: Life | Q33: 1 | S33: 5460147 | T33: 5460147 | U33: 5460147 | W33: 5054523.3 | X33: 0 | Z33: 45401 | AA33: 50854 | AC33: IPCA | AE33: 0.105 | AF33: 252 | AG33: Percentual variavel, periodos uniformes, sobre valor remanescente
A34: 2 | B34: CRI | C34: 24D3313141 | D34: 10 | F34: 45401 | G34: RCVM 60 | I34: BRLGOSCRI1L2 | J34: CCI | K34: Fundo Artemis | L34: LOGOS COMPANHIA SECURITIZADORA S/A | M34: Vortx DTVM Ltda. | P34: Life | Q34: 1 | S34: 5297424 | T34: 5297424 | U34: 5297424 | W34: 4921596.1 | X34: 0 | Z34: 45401 | AA34: 50854 | AC34: IPCA | AE34: 0.105 | AF34: 252 | AG34: Percentual variavel, periodos uniformes, sobre valor remanescente
A35: 2 | B35: CRI | C35: 24D3313259 | D35: 11 | F35: 45401 | G35: RCVM 60 | I35: BRLGOSCRI1M0 | J35: CCI | K35: Fundo Artemis | L35: LOGOS COMPANHIA SECURITIZADORA S/A | M35: Vortx DTVM Ltda. | P35: Life | Q35: 1 | S35: 5421143 | T35: 5421143 | U35: 5421143 | W35: 5212901.6 | X35: 0 | Z35: 45401 | AA35: 50854 | AC35: IPCA | AE35: 0.105 | AF35: 252 | AG35: Percentual variavel, periodos uniformes, sobre valor remanescente
A36: 2 | B36: CRI | C36: 24D3313323 | D36: 12 | F36: 45401 | G36: RCVM 60 | I36: BRLGOSCRI1N8 | J36: CCI | K36: Fundo Artemis | L36: LOGOS COMPANHIA SECURITIZADORA S/A | M36: Vortx DTVM Ltda. | P36: Life | Q36: 1 | S36: 4118100 | T36: 4118100 | U36: 4118100 | W36: 3961698.8 | X36: 0 | Z36: 45401 | AA36: 50854 | AC36: IPCA | AE36: 0.105 | AF36: 252 | AG36: Percentual variavel, periodos uniformes, sobre valor remanescente
A37: 2 | B37: CRI | C37: 24H1626820 | D37: 13 | F37: 45519 | G37: RCVM 60 | I37: BRLGOSCRI1O6 | J37: CCI | K37: Fundo Artemis | L37: LOGOS COMPANHIA SECURITIZADORA S/A | M37: Vortx DTVM Ltda. | P37: Life | Q37: 1 | S37: 5047048 | T37: 5047048 | U37: 5047048 | Z37: =F37 -> 45519 | AA37: 50885 | AC37: IPCA | AE37: 0.105 | AF37: 253 | AG37: Percentual variavel, periodos uniformes, sobre valor remanescente
A38: 2 | B38: CRI | C38: 24H1626902 | D38: 14 | F38: 45519 | G38: RCVM 60 | I38: BRLGOSCRI1P3 | J38: CCI | K38: Fundo Artemis | L38: LOGOS COMPANHIA SECURITIZADORA S/A | M38: Vortx DTVM Ltda. | P38: Life | Q38: 1 | S38: 6006205 | T38: 6006205 | U38: 5818686 | V38: CANCELAR CRIS | Z38: =F38 -> 45519 | AA38: 50885 | AC38: IPCA | AE38: 0.105 | AF38: 254 | AG38: Percentual variavel, periodos uniformes, sobre valor remanescente
A39: 2 | B39: CRI | C39: 25A3984169 | D39: 15 | F39: 45681 | G39: RCVM 60 | I39: BRLGOSCRI1Q1 | J39: CCI | K39: Fundo Artemis | L39: LOGOS COMPANHIA SECURITIZADORA S/A | M39: Vortx DTVM Ltda. | P39: Life | Q39: 1 | S39: 5006524 | T39: 5006524 | U39: 5006524 | Z39: =F39 -> 45681 | AA39: 51007 | AC39: IPCA | AE39: 0.12 | AF39: 255 | AG39: Percentual variavel, periodos uniformes, sobre valor remanescente
A40: 2 | B40: CRI | C40: 25A3985624 | D40: 16 | F40: 45681 | G40: RCVM 60 | I40: BRLGOSCRI1R9 | J40: CCI | K40: Fundo Artemis | L40: LOGOS COMPANHIA SECURITIZADORA S/A | M40: Vortx DTVM Ltda. | P40: Life | Q40: 1 | S40: 4999991 | T40: 4999991 | U40: 4999991 | Z40: =F40 -> 45681 | AA40: 51007 | AC40: IPCA | AE40: 0.12 | AF40: 256 | AG40: Percentual variavel, periodos uniformes, sobre valor remanescente
...

Sheet Prestadores de Serviço
B2: egoria | C2: Campo | D2: Tipo de Dado | E2: Obrigatório? | F2: Exemplo
B3: Dados Cadastrais | C3: Razão Social | D3: Texto | E3: Sim | F3: XYZ Indústria Ltda.
C4: Nome Fantasia | D4: Texto | E4: Não | F4: XYZ Soluções
C5: CNPJ | D5: Número (14 dígitos) | E5: Sim | F5: 12.345.678/0001-99
C6: Inscrição Estadual (IE) | D6: Texto | E6: Depende* | F6: 123456789112
C7: Inscrição Municipal (IM) | D7: Texto | E7: Depende* | F7: 987654
C8: Data de Abertura | D8: Data | E8: Sim | F8: 40252
C9: CNAE Principal | D9: Número (7 dígitos) | E9: Sim | F9: 2829-1/00
B10: Dados Fiscais | C10: Regime Tributário | D10: Lista (Simples, Lucro Real/Presumido) | E10: Sim | F10: Simples Nacional
C11: Optante pelo SIMPLES? | D11: Sim/Não | E11: Sim | F11: Sim
C12: Substituição Tributária? | D12: Sim/Não | E12: Sim | F12: Não
C13: Certificado Digital (e-CNPJ)? | D13: Sim/Não | E13: Não | F13: Sim
B14: Endereço | C14: Logradouro | D14: Texto | E14: Sim | F14: Av. das Indústrias
C15: Número | D15: Texto/Número | E15: Sim | F15: 1500
C16: Complemento | D16: Texto | E16: Não | F16: Bloco B, Sala 301
C17: Bairro | D17: Texto | E17: Sim | F17: Industrial
C18: Cidade | D18: Texto | E18: Sim | F18: São Paulo
C19: UF | D19: Lista (BR) | E19: Sim | F19: SP
C20: CEP | D20: Número (8 dígitos) | E20: Sim | F20: 01234-567
B21: Contato | C21: Telefone Principal | D21: Texto | E21: Sim | F21: (11) 98765-4321
C22: E-mail | D22: E-mail | E22: Sim | F22: contato@xyz.com.br
C23: Nome do Responsável | D23: Texto | E23: Sim | F23: João Silva
C24: Cargo do Responsável | D24: Texto | E24: Não | F24: Gerente Comercial
B25: Dados Bancários | C25: Banco | D25: Texto | E25: Não | F25: Banco do Brasil
C26: Agência | D26: Número | E26: Não | F26: 1234
C27: Conta Corrente | D27: Número/Texto | E27: Não | F27: 56789-0
C28: Tipo de Conta (Corrente/Poupança) | D28: Lista | E28: Não | F28: Corrente
C29: Pix (Chave) | D29: Texto | E29: Não | F29: 12.345.678/0001-99 (CNPJ)
B30: Informações Adicionais | C30: Produtos/Serviços Fornecidos | D30: Texto | E30: Não | F30: Peças automotivas
C31: Prazo de Entrega Médio | D31: Texto | E31: Não | F31: 15 dias úteis
C32: Condições de Pagamento | D32: Texto | E32: Não | F32: 30 dias após fatura
C33: Observações | D33: Texto Livre | E33: Não | F33: Fornecedor preferencial desde 2018

Sheet Investidores
A2: Dados Pessoais
A3: Código do Cliente | B3: Nome do Cliente | C3: CPF | D3: Tipo de documento | E3: Número do documento | F3: Data de emissão | G3: Órgão Emissor | H3: UF do emissor | I3: Data de Nascimento | J3: Sexo | K3: Local de Nascimento | L3: UF (Nascimento) | M3: País de Nascimento | N3: País de Residência Fiscal | O3: NIF | P3: Nome do Pai | Q3: Nome da Mãe | R3: Estado Civil | S3: Nome do Cônjuge | T3: Endereço | U3: Número | V3: Complemento | W3: Bairro | X3: Cidade | Y3: UF | Z3: CEP | AA3: Caixa Postal | AB3: Skype | AC3: Telefone Residencial | AD3: Celular | AE3: E-mail | AF3: Ocupação Principal | AG3: Cargo/Função | AH3: Empresa que Trabalha | AI3: Endereço Comercial | AJ3: Número | AK3: Complemento | AL3: Bairro | AM3: Cidade | AN3: UF | AO3: CEP | AP3: Caixa Postal | AQ3: Skype | AR3: Telefone Comercial | AS3: Celular | AT3: E-mail | AU3: Endereço para correspondência | AV3: Banco | AW3: Agência | AX3: Número da Conta | AY3: Co-Titular | AZ3: CPF do Co-Titular | BA3: Bens Imóveis (Tipo) | BB3: Endereço do Imóvel | BC3: Cidade | BD3: UF | BE3: Valor | BF3: Outros Bens (Tipo) | BG3: Descrição | BH3: Valor | BI3: Ativos Financeiros | BJ3: Descrição | BK3: Valor | BL3: Salário/Pró Labore | BM3: Outros Rendimentos | BN3: Valor Total (Patrimônio) | BO3: Opera por conta própria? | BP3: Pessoa Vinculada à Securitizadora? | BQ3: Pessoa Politicamente Exposta? | BR3: Autoriza transmissão por procurador? | BS3: Forma de transmissão de ordens: Verbal ( ) / Escrito ( ) | BT3: Permite carteira própria como contraparte? (Concordo/Não Concordo/Consulta) | BU3: É US Person? | BV3: País de nascimento/cidadania é EUA? | BW3: Possui Green Card? | BX3: Residência fiscal nos EUA? | BY3: Americano Naturalizado? | BZ3: Pai/Mãe estrangeiros? (Se sim, país) | CA3: Assinatura do Cliente | CB3: Data_assinatura_cad_inv | CC3: Nome do Responsável (Securitizadora) | CD3: Assinatura do Responsável | CE3: Data_conferencia_cad_inv | CF3: Banco_custodiante | CG3: Conta_banco_custodiante

Sheet Distribuiçōes
A1: Data | B1: Tipo ativo | C1: Codigo_if | D1: Preço Unitário | E1: Quantidades | F1: Valor total | G1: Escriturador | H1: Conta Escriturador | I1: Coordenador Lider | J1: Conta Emissor | K1: Conta Coordenador Líder | L1: Investidor

Sheet Resumo
A1: Operação | B1: Saldo Devedor | C1: Saldo Devedor | D1: Gestão | E1: Servicer | F1: TOTAL
A2: 4ª Série - Paysage | B2: =VLOOKUP(A2,'Características de CRI - LOGOS'!$A$2:$K$36,7,0) -> #N/A | C2: =SUMIF('Características de CRI - LOGOS'!#REF!,Resumo!A2,'Características de CRI - LOGOS'!$W$2:$W$43) -> #REF! | D2: 10284.84 | E2: 902.91749 | F2: =SUM(D2:E2) -> 11187.757
A3: 12ª Série - Paysage | B3: =VLOOKUP(A3,'Características de CRI - LOGOS'!$A$2:$K$36,7,0) -> #N/A | C3: =SUMIF('Características de CRI - LOGOS'!#REF!,Resumo!A3,'Características de CRI - LOGOS'!$W$2:$W$43) -> #REF! | D3: 19068.95 | E3: 2081.168 | F3: =SUM(D3:E3) -> 21150.118
A4: 18ª, 19ª, 20ª Séries - Premoaço | B4: =VLOOKUP(A4,'Características de CRI - LOGOS'!$A$2:$K$36,7,0) -> #N/A | C4: =SUMIF('Características de CRI - LOGOS'!#REF!,Resumo!A4,'Características de CRI - LOGOS'!$W$2:$W$43) -> #REF! | D4: 11388.81 | F4: =SUM(D4:E4) -> 11388.81
A5: 22ª Série - Rodobens | B5: =VLOOKUP(A5,'Características de CRI - LOGOS'!$A$2:$K$36,7,0) -> #N/A | C5: =SUMIF('Características de CRI - LOGOS'!#REF!,Resumo!A5,'Características de CRI - LOGOS'!$W$2:$W$43) -> #REF! | D5: 0 | F5: =SUM(D5:E5) -> 0
A6: 27ª, 28ª Séries - Paysage | B6: =VLOOKUP(A6,'Características de CRI - LOGOS'!$A$2:$K$36,7,0) -> #N/A | C6: =SUMIF('Características de CRI - LOGOS'!#REF!,Resumo!A6,'Características de CRI - LOGOS'!$W$2:$W$43) -> #REF! | D6: =5441.29+1990.88+1138.36 -> 8570.53 | E6: 2106.0736 | F6: =SUM(D6:E6) -> 10676.604
A7: 29ª, 30ª e 37ª Séries - Tecnobens | B7: =VLOOKUP(A7,'Características de CRI - LOGOS'!$A$2:$K$36,7,0) -> #N/A | C7: =SUMIF('Características de CRI - LOGOS'!#REF!,Resumo!A7,'Características de CRI - LOGOS'!$W$2:$W$43) -> #REF! | D7: 11700.36 | E7: 813.06 | F7: =SUM(D7:E7) -> 12513.42
A8: 31ª, 32ª e 46ª Séries - DJR | B8: =VLOOKUP(A8,'Características de CRI - LOGOS'!$A$2:$K$36,7,0) -> #N/A | C8: =SUMIF('Características de CRI - LOGOS'!#REF!,Resumo!A8,'Características de CRI - LOGOS'!$W$2:$W$43) -> #REF! | D8: 0 | F8: =SUM(D8:E8) -> 0
A9: 33ª Série - Paysage | B9: =VLOOKUP(A9,'Características de CRI - LOGOS'!$A$2:$K$36,7,0) -> #N/A | C9: =SUMIF('Características de CRI - LOGOS'!#REF!,Resumo!A9,'Características de CRI - LOGOS'!$W$2:$W$43) -> #REF! | D9: 8333.46 | F9: =SUM(D9:E9) -> 8333.46
A10: 35ª e 36ª - Mascor | B10: =VLOOKUP(A10,'Características de CRI - LOGOS'!$A$2:$K$36,7,0) -> #N/A | C10: =SUMIF('Características de CRI - LOGOS'!#REF!,Resumo!A10,'Características de CRI - LOGOS'!$W$2:$W$43) -> #REF! | D10: 17011.59 | F10: =SUM(D10:E10) -> 17011.59
A11: 38ª, 39ª e 47ª Séries - CiaTC | B11: =VLOOKUP(A11,'Características de CRI - LOGOS'!$A$2:$K$36,7,0) -> #N/A | C11: =SUMIF('Características de CRI - LOGOS'!#REF!,Resumo!A11,'Características de CRI - LOGOS'!$W$2:$W$43) -> #REF! | D11: 75000 | F11: =SUM(D11:E11) -> 75000
A12: 40ª, 41ª, 42ª, 48ª e 49ª Séries - Life | B12: =VLOOKUP(A12,'Características de CRI - LOGOS'!$A$2:$K$36,7,0) -> #N/A | C12: =SUMIF('Características de CRI - LOGOS'!#REF!,Resumo!A12,'Características de CRI - LOGOS'!$W$2:$W$43) -> #REF! | D12: 16456.67 | F12: =SUM(D12:E12) -> 16456.67
A13: 45ª Série - Paysage | B13: =VLOOKUP(A13,'Características de CRI - LOGOS'!$A$2:$K$36,7,0) -> #N/A | C13: =SUMIF('Características de CRI - LOGOS'!#REF!,Resumo!A13,'Características de CRI - LOGOS'!$W$2:$W$43) -> #REF! | D13: 6702 | F13: =SUM(D13:E13) -> 6702
A14: 1ª a 12ª Séries - Fundo Artemis | B14: =VLOOKUP(A14,'Características de CRI - LOGOS'!$A$2:$K$36,7,0) -> #N/A | C14: =SUMIF('Características de CRI - LOGOS'!#REF!,Resumo!A14,'Características de CRI - LOGOS'!$W$2:$W$43) -> #REF! | D14: 5500 | F14: =SUM(D14:E14) -> 5500
C15: =SUM(C2:C14) -> #REF! | D15: =SUM(D2:D14) -> 190017.21 | E15: =SUM(E2:E14) -> 5903.2191 | F15: =SUM(F2:F14) -> 195920.43
