Workbook
Name FDSFER: #REF!
Name FER: #REF!
Name MATRIZ: #REF!

Sheet PU
A1: LOGOS SECURITIZADORA | J1: Data de Vencimento: | K1: 46241
A2: 16ª Série da 1ª Emissão (18C0722274) | J2: Data de Emissão: | K2: 43171
A3: dC | B3: dJ | C3: DATA | D3: VNe | E3: Fator IPCA | F3: VNa | G3: FatorJuros | H3: JUROS | I3: PU | J3: Valor Nominal Emissão: | K3: 10000 | M3: 2300000
G4: 0.085 | J4: Início da Rentabilidade | K4: 43175 | M4: 1.15
A5: 0 | B5: 0 | C5: =K2 | D5: =TRUNC(($K$3),8) | E5: 1 | F5: =TRUNC((D5*E5),8) | G5: =ROUND(((ROUND((1+$G$4)^TRUNC((1*30/360),9),9))^TRUNC((B5/31),9)),9) | H5: =TRUNC((F5*G5-F5),8) | I5: =F5+H5 | M5: 30/10/2025 23:53:03
A6: 0 | B6: 0 | C6: =C5+1 | D6: =IF(DAY(C6)=DAY($K$1+1),TRUNC(($D$5),8),D5) | E6: 1 | F6: =TRUNC((D6*E6),8) | G6: =ROUND(((1+$G$4)^(30/360))^(B6/31),9) | H6: =TRUNC((F6*G6-F6),8) | I6: =F6+H6
A7: 0 | B7: 0 | C7: =C6+1 | D7: =IF(DAY(C7)=DAY($K$1+1),TRUNC(($D$5),8),D6) | E7: 1 | F7: =TRUNC((D7*E7),8) | G7: =ROUND(((1+$G$4)^(30/360))^(B7/31),9) | H7: =TRUNC((F7*G7-F7),8) | I7: =F7+H7
A8: 0 | B8: 0 | C8: =C7+1 | D8: =IF(DAY(C8)=DAY($K$1+1),TRUNC(($D$5),8),D7) | E8: 1 | F8: =TRUNC((D8*E8),8) | G8: =ROUND(((1+$G$4)^(30/360))^(B8/31),9) | H8: =TRUNC((F8*G8-F8),8) | I8: =F8+H8
A9: 0 | B9: 0 | C9: =C8+1 | D9: =IF(DAY(C9)=DAY($K$1+1),TRUNC(($D$5),8),D8) | E9: 1 | F9: =TRUNC((D9*E9),8) | G9: =ROUND(((1+$G$4)^(30/360))^(B9/31),9) | H9: =TRUNC((F9*G9-F9),8) | I9: =F9+H9
A10: =IF(DAY(C10)=DAY($K$1+1),1,A9+1) | B10: =IF(DAY(C10)=DAY($K$1+1),1,B9+1) | C10: =C9+1 | D10: =IF(DAY(C10)=DAY($K$1+1),TRUNC(($D$5),8),D9) | E10: =TRUNC(((1+IPCA!#REF!))^(A10/22),8) | F10: =TRUNC((D10*E10),8) | G10: =ROUND(((1+$G$4)^(30/360))^(B10/31),9) | H10: =TRUNC((F10*G10-F10),8) | I10: =F10+H10
A11: =IF(DAY(C11)=DAY($K$1+1),1,A10+1) | B11: =IF(DAY(C11)=DAY($K$1+1),1,B10+1) | C11: =C10+1 | D11: =IF(DAY(C11)=DAY($K$1+1),TRUNC(($D$5),8),D10) | E11: =TRUNC(((1+IPCA!#REF!))^(A11/22),8) | F11: =TRUNC((D11*E11),8) | G11: =ROUND(((1+$G$4)^(30/360))^(B11/31),9) | H11: =TRUNC((F11*G11-F11),8) | I11: =F11+H11
A12: =IF(DAY(C12)=DAY($K$1+1),1,A11+1) | B12: =IF(DAY(C12)=DAY($K$1+1),1,B11+1) | C12: =C11+1 | D12: =IF(DAY(C12)=DAY($K$1+1),TRUNC(($D$5),8),D11) | E12: =TRUNC(((1+IPCA!#REF!))^(A12/22),8) | F12: =TRUNC((D12*E12),8) | G12: =ROUND(((1+$G$4)^(30/360))^(B12/31),9) | H12: =TRUNC((F12*G12-F12),8) | I12: =F12+H12
A13: =IF(DAY(C13)=DAY($K$1+1),1,A12+1) | B13: =IF(DAY(C13)=DAY($K$1+1),1,B12+1) | C13: =C12+1 | D13: =IF(DAY(C13)=DAY($K$1+1),TRUNC(($D$5),8),D12) | E13: =TRUNC(((1+IPCA!#REF!))^(A13/22),8) | F13: =TRUNC((D13*E13),8) | G13: =ROUND(((1+$G$4)^(30/360))^(B13/31),9) | H13: =TRUNC((F13*G13-F13),8) | I13: =F13+H13
A14: =IF(DAY(C14)=DAY($K$1+1),1,A13+1) | B14: =IF(DAY(C14)=DAY($K$1+1),1,B13+1) | C14: =C13+1 | D14: =IF(DAY(C14)=DAY($K$1+1),TRUNC(($D$5),8),D13) | E14: =TRUNC(((1+IPCA!#REF!))^(A14/22),8) | F14: =TRUNC((D14*E14),8) | G14: =ROUND(((1+$G$4)^(30/360))^(B14/31),9) | H14: =TRUNC((F14*G14-F14),8) | I14: =F14+H14
A15: =IF(DAY(C15)=DAY($K$1+1),1,A14+1) | B15: =IF(DAY(C15)=DAY($K$1+1),1,B14+1) | C15: =C14+1 | D15: =IF(DAY(C15)=DAY($K$1+1),TRUNC(($D$5),8),D14) | E15: =TRUNC(((1+IPCA!#REF!))^(A15/22),8) | F15: =TRUNC((D15*E15),8) | G15: =ROUND(((1+$G$4)^(30/360))^(B15/31),9) | H15: =TRUNC((F15*G15-F15),8) | I15: =F15+H15
A16: =IF(DAY(C16)=DAY($K$1+1),1,A15+1) | B16: =IF(DAY(C16)=DAY($K$1+1),1,B15+1) | C16: =C15+1 | D16: =IF(DAY(C16)=DAY($K$1+1),TRUNC(($D$5),8),D15) | E16: =TRUNC(((1+IPCA!#REF!))^(A16/22),8) | F16: =TRUNC((D16*E16),8) | G16: =ROUND(((1+$G$4)^(30/360))^(B16/31),9) | H16: =TRUNC((F16*G16-F16),8) | I16: =F16+H16
A17: =IF(DAY(C17)=DAY($K$1+1),1,A16+1) | B17: =IF(DAY(C17)=DAY($K$1+1),1,B16+1) | C17: =C16+1 | D17: =IF(DAY(C17)=DAY($K$1+1),TRUNC(($D$5),8),D16) | E17: =TRUNC(((1+IPCA!#REF!))^(A17/22),8) | F17: =TRUNC((D17*E17),8) | G17: =ROUND(((1+$G$4)^(30/360))^(B17/31),9) | H17: =TRUNC((F17*G17-F17),8) | I17: =F17+H17
A18: =IF(DAY(C18)=DAY($K$1+1),1,A17+1) | B18: =IF(DAY(C18)=DAY($K$1+1),1,B17+1) | C18: =C17+1 | D18: =IF(DAY(C18)=DAY($K$1+1),TRUNC(($D$5),8),D17) | E18: =TRUNC(((1+IPCA!#REF!))^(A18/22),8) | F18: =TRUNC((D18*E18),8) | G18: =ROUND(((1+$G$4)^(30/360))^(B18/31),9) | H18: =TRUNC((F18*G18-F18),8) | I18: =F18+H18
A19: =IF(DAY(C19)=DAY($K$1+1),1,A18+1) | B19: =IF(DAY(C19)=DAY($K$1+1),1,B18+1) | C19: =C18+1 | D19: =IF(DAY(C19)=DAY($K$1+1),TRUNC(($D$5),8),D18) | E19: =TRUNC(((1+IPCA!#REF!))^(A19/22),8) | F19: =TRUNC((D19*E19),8) | G19: =ROUND(((1+$G$4)^(30/360))^(B19/31),9) | H19: =TRUNC((F19*G19-F19),8) | I19: =F19+H19
A20: =IF(DAY(C20)=DAY($K$1+1),1,A19+1) | B20: =IF(DAY(C20)=DAY($K$1+1),1,B19+1) | C20: =C19+1 | D20: =IF(DAY(C20)=DAY($K$1+1),TRUNC(($D$5),8),D19) | E20: =TRUNC(((1+IPCA!#REF!))^(A20/22),8) | F20: =TRUNC((D20*E20),8) | G20: =ROUND(((1+$G$4)^(30/360))^(B20/(EDATE(C20-A20,1)-(C20-A20))),9) | H20: =TRUNC((F20*G20-F20),8) | I20: =F20+H20
A21: =IF(DAY(C21)=DAY($K$1+1),1,A20+1) | B21: =IF(DAY(C21)=DAY($K$1+1),1,B20+1) | C21: =C20+1 | D21: =IF(DAY(C21)=DAY($K$1+1),TRUNC(($D$5),8),D20) | E21: =TRUNC(((1+IPCA!#REF!))^(A21/22),8) | F21: =TRUNC((D21*E21),8) | G21: =ROUND(((1+$G$4)^(30/360))^(B21/(EDATE(C21-A21,1)-(C21-A21))),9) | H21: =TRUNC((F21*G21-F21),8) | I21: =F21+H21
A22: =IF(DAY(C22)=DAY($K$1+1),1,A21+1) | B22: =IF(DAY(C22)=DAY($K$1+1),1,B21+1) | C22: =C21+1 | D22: =IF(DAY(C22)=DAY($K$1+1),TRUNC(($D$5),8),D21) | E22: =TRUNC(((1+IPCA!#REF!))^(A22/22),8) | F22: =TRUNC((D22*E22),8) | G22: =ROUND(((1+$G$4)^(30/360))^(B22/(EDATE(C22-A22,1)-(C22-A22))),9) | H22: =TRUNC((F22*G22-F22),8) | I22: =F22+H22
A23: =IF(DAY(C23)=DAY($K$1+1),1,A22+1) | B23: =IF(DAY(C23)=DAY($K$1+1),1,B22+1) | C23: =C22+1 | D23: =IF(DAY(C23)=DAY($K$1+1),TRUNC(($D$5),8),D22) | E23: =TRUNC(((1+IPCA!#REF!))^(A23/22),8) | F23: =TRUNC((D23*E23),8) | G23: =ROUND(((1+$G$4)^(30/360))^(B23/(EDATE(C23-A23,1)-(C23-A23))),9) | H23: =TRUNC((F23*G23-F23),8) | I23: =F23+H23
A24: =IF(DAY(C24)=DAY($K$1+1),1,A23+1) | B24: =IF(DAY(C24)=DAY($K$1+1),1,B23+1) | C24: =C23+1 | D24: =IF(DAY(C24)=DAY($K$1+1),TRUNC(($D$5),8),D23) | E24: =TRUNC(((1+IPCA!#REF!))^(A24/22),8) | F24: =TRUNC((D24*E24),8) | G24: =ROUND(((1+$G$4)^(30/360))^(B24/(EDATE(C24-A24,1)-(C24-A24))),9) | H24: =TRUNC((F24*G24-F24),8) | I24: =F24+H24
A25: =IF(DAY(C25)=DAY($K$1+1),1,A24+1) | B25: =IF(DAY(C25)=DAY($K$1+1),1,B24+1) | C25: =C24+1 | D25: =IF(DAY(C25)=DAY($K$1+1),TRUNC(($D$5),8),D24) | E25: =TRUNC(((1+IPCA!#REF!))^(A25/22),8) | F25: =TRUNC((D25*E25),8) | G25: =ROUND(((1+$G$4)^(30/360))^(B25/(EDATE(C25-A25,1)-(C25-A25))),9) | H25: =TRUNC((F25*G25-F25),8) | I25: =F25+H25
A26: =IF(DAY(C26)=DAY($K$1+1),1,A25+1) | B26: =IF(DAY(C26)=DAY($K$1+1),1,B25+1) | C26: =C25+1 | D26: =IF(DAY(C26)=DAY($K$1+1),TRUNC(($D$5),8),D25) | E26: =TRUNC(((1+IPCA!#REF!))^(A26/22),8) | F26: =TRUNC((D26*E26),8) | G26: =ROUND(((1+$G$4)^(30/360))^(B26/(EDATE(C26-A26,1)-(C26-A26))),9) | H26: =TRUNC((F26*G26-F26),8) | I26: =F26+H26
A27: =IF(DAY(C27)=DAY($K$1+1),1,A26+1) | B27: =IF(DAY(C27)=DAY($K$1+1),1,B26+1) | C27: =C26+1 | D27: =IF(DAY(C27)=DAY($K$1+1),TRUNC(($D$5),8),D26) | E27: =TRUNC(((1+IPCA!#REF!))^(A27/22),8) | F27: =TRUNC((D27*E27),8) | G27: =ROUND(((1+$G$4)^(30/360))^(B27/(EDATE(C27-A27,1)-(C27-A27))),9) | H27: =TRUNC((F27*G27-F27),8) | I27: =F27+H27
A28: =IF(DAY(C28)=DAY($K$1+1),1,A27+1) | B28: =IF(DAY(C28)=DAY($K$1+1),1,B27+1) | C28: =C27+1 | D28: =IF(DAY(C28)=DAY($K$1+1),TRUNC(($D$5),8),D27) | E28: =TRUNC(((1+IPCA!#REF!))^(A28/22),8) | F28: =TRUNC((D28*E28),8) | G28: =ROUND(((1+$G$4)^(30/360))^(B28/(EDATE(C28-A28,1)-(C28-A28))),9) | H28: =TRUNC((F28*G28-F28),8) | I28: =F28+H28
A29: =IF(DAY(C29)=DAY($K$1+1),1,A28+1) | B29: =IF(DAY(C29)=DAY($K$1+1),1,B28+1) | C29: =C28+1 | D29: =IF(DAY(C29)=DAY($K$1+1),TRUNC(($D$5),8),D28) | E29: =TRUNC(((1+IPCA!#REF!))^(A29/22),8) | F29: =TRUNC((D29*E29),8) | G29: =ROUND(((1+$G$4)^(30/360))^(B29/(EDATE(C29-A29,1)-(C29-A29))),9) | H29: =TRUNC((F29*G29-F29),8) | I29: =F29+H29
A30: =IF(DAY(C30)=DAY($K$1+1),1,A29+1) | B30: =IF(DAY(C30)=DAY($K$1+1),1,B29+1) | C30: =C29+1 | D30: =IF(DAY(C30)=DAY($K$1+1),TRUNC(($D$5),8),D29) | E30: =TRUNC(((1+IPCA!#REF!))^(A30/22),8) | F30: =TRUNC((D30*E30),8) | G30: =ROUND(((1+$G$4)^(30/360))^(B30/(EDATE(C30-A30,1)-(C30-A30))),9) | H30: =TRUNC((F30*G30-F30),8) | I30: =F30+H30 | J30: JUROS | K30: AMORTIZAÇÃO | L30: AMEX | M30: RESIDUAL
A31: =IF(DAY(C31)=DAY($K$1+1),1,A30+1) | B31: =IF(DAY(C31)=DAY($K$1+1),1,B30+1) | C31: =C30+1 | D31: =IF(DAY(C31)=DAY($K$1+1),TRUNC(($D$5),8),D30) | E31: =TRUNC(((1+IPCA!#REF!))^(A31/22),8) | F31: =TRUNC((D31*E31),8) | G31: =ROUND(((1+$G$4)^(30/360))^(B31/(EDATE(C31-A31,1)-(C31-A31))),9) | H31: =TRUNC((F31*G31-F31),8) | I31: =F31+H31 | J31: =H31 | K31: 0 | L31: =L32/1540 | M31: =I31-J31-K31-L31
A32: =IF(DAY(C32)=DAY($K$1+1),1,A31+1) | B32: =IF(DAY(C32)=DAY($K$1+1),1,B31+1) | C32: =C31+1 | D32: =M31 | E32: =TRUNC(((1+IPCA!#REF!))^(A32/30),8) | F32: =TRUNC((D32*E32),8) | G32: =ROUND(((1+$G$4)^(30/360))^(B32/(EDATE(C32-A32,1)-(C32-A32))),9) | H32: =TRUNC((F32*G32-F32),8) | I32: =F32+H32 | J32: =J31*1540 | K32: =K31*1540 | L32: =(147598.16*0.7) | M32: =M31*1540
A33: =IF(DAY(C33)=DAY($K$1+1),1,A32+1) | B33: =IF(DAY(C33)=DAY($K$1+1),1,B32+1) | C33: =C32+1 | D33: =IF(DAY(C33)=DAY($K$1+1),TRUNC(($D$5),8),D32) | E33: =TRUNC(((1+IPCA!#REF!))^(A33/30),8) | F33: =TRUNC((D33*E33),8) | G33: =ROUND(((1+$G$4)^(30/360))^(B33/(EDATE(C33-A33,1)-(C33-A33))),9) | H33: =TRUNC((F33*G33-F33),8) | I33: =F33+H33
A34: =IF(DAY(C34)=DAY($K$1+1),1,A33+1) | B34: =IF(DAY(C34)=DAY($K$1+1),1,B33+1) | C34: =C33+1 | D34: =IF(DAY(C34)=DAY($K$1+1),TRUNC(($D$5),8),D33) | E34: =TRUNC(((1+IPCA!#REF!))^(A34/30),8) | F34: =TRUNC((D34*E34),8) | G34: =ROUND(((1+$G$4)^(30/360))^(B34/(EDATE(C34-A34,1)-(C34-A34))),9) | H34: =TRUNC((F34*G34-F34),8) | I34: =F34+H34 | J34: =SUM(J32:K32) | K34: TOTAL PMT
A35: =IF(DAY(C35)=DAY($K$1+1),1,A34+1) | B35: =IF(DAY(C35)=DAY($K$1+1),1,B34+1) | C35: =C34+1 | D35: =IF(DAY(C35)=DAY($K$1+1),TRUNC(($D$5),8),D34) | E35: =TRUNC(((1+IPCA!#REF!))^(A35/30),8) | F35: =TRUNC((D35*E35),8) | G35: =ROUND(((1+$G$4)^(30/360))^(B35/(EDATE(C35-A35,1)-(C35-A35))),9) | H35: =TRUNC((F35*G35-F35),8) | I35: =F35+H35 | J35: =SUM(J32:L32)
A36: =IF(DAY(C36)=DAY($K$1+1),1,A35+1) | B36: =IF(DAY(C36)=DAY($K$1+1),1,B35+1) | C36: =C35+1 | D36: =IF(DAY(C36)=DAY($K$1+1),TRUNC(($D$5),8),D35) | E36: =TRUNC(((1+IPCA!#REF!))^(A36/30),8) | F36: =TRUNC((D36*E36),8) | G36: =ROUND(((1+$G$4)^(30/360))^(B36/(EDATE(C36-A36,1)-(C36-A36))),9) | H36: =TRUNC((F36*G36-F36),8) | I36: =F36+H36
A37: =IF(DAY(C37)=DAY($K$1+1),1,A36+1) | B37: =IF(DAY(C37)=DAY($K$1+1),1,B36+1) | C37: =C36+1 | D37: =IF(DAY(C37)=DAY($K$1+1),TRUNC(($D$5),8),D36) | E37: =TRUNC(((1+IPCA!#REF!))^(A37/30),8) | F37: =TRUNC((D37*E37),8) | G37: =ROUND(((1+$G$4)^(30/360))^(B37/(EDATE(C37-A37,1)-(C37-A37))),9) | H37: =TRUNC((F37*G37-F37),8) | I37: =F37+H37
A38: =IF(DAY(C38)=DAY($K$1+1),1,A37+1) | B38: =IF(DAY(C38)=DAY($K$1+1),1,B37+1) | C38: =C37+1 | D38: =IF(DAY(C38)=DAY($K$1+1),TRUNC(($D$5),8),D37) | E38: =TRUNC(((1+IPCA!#REF!))^(A38/30),8) | F38: =TRUNC((D38*E38),8) | G38: =ROUND(((1+$G$4)^(30/360))^(B38/(EDATE(C38-A38,1)-(C38-A38))),9) | H38: =TRUNC((F38*G38-F38),8) | I38: =F38+H38
A39: =IF(DAY(C39)=DAY($K$1+1),1,A38+1) | B39: =IF(DAY(C39)=DAY($K$1+1),1,B38+1) | C39: =C38+1 | D39: =IF(DAY(C39)=DAY($K$1+1),TRUNC(($D$5),8),D38) | E39: =TRUNC(((1+IPCA!#REF!))^(A39/30),8) | F39: =TRUNC((D39*E39),8) | G39: =ROUND(((1+$G$4)^(30/360))^(B39/(EDATE(C39-A39,1)-(C39-A39))),9) | H39: =TRUNC((F39*G39-F39),8) | I39: =F39+H39
A40: =IF(DAY(C40)=DAY($K$1+1),1,A39+1) | B40: =IF(DAY(C40)=DAY($K$1+1),1,B39+1) | C40: =C39+1 | D40: =IF(DAY(C40)=DAY($K$1+1),TRUNC(($D$5),8),D39) | E40: =TRUNC(((1+IPCA!#REF!))^(A40/30),8) | F40: =TRUNC((D40*E40),8) | G40: =ROUND(((1+$G$4)^(30/360))^(B40/(EDATE(C40-A40,1)-(C40-A40))),9) | H40: =TRUNC((F40*G40-F40),8) | I40: =F40+H40
...

Sheet 22F1187231
B1: LOGOS SECURITIZADORA | K1: Data de Vencimento: | L1: 48908 | N1: 1ª Integralização:
B2: 46ª Série da 1ª Emissão (22F1187231) | K2: Data de Emissão: | L2: 44739 | N2: 44754
B3: dC | C3: dJ | D3: DATA | E3: VNe | F3: Fator IPCA | G3: VNa | H3: FatorJuros | I3: JUROS | J3: PU | K3: Valor Nominal Emissão: | L3: 1 | N3: 1113210
H4: 0.095 | K4: Início da Rentabilidade | L4: 44754 | M4: (J + A)
A5: 1 | B5: 0 | C5: 0 | D5: 44753 | E5: 1 | F5: =TRUNC(((1+VLOOKUP(A5,IPCA!$A$2:$C$140,3,0)))^(C5/30),8) | G5: =TRUNC((E5*F5),8) | H5: =ROUND(((1+$H$4)^(30/360))^(C5/30),9) | I5: =TRUNC((G5*H5-G5),8) | J5: =G5+I5
A6: 1 | B6: =IF(DAY(D6)=DAY($L$1+1),1,B5+1) | C6: =IF(DAY(D6)=DAY($L$1+1),1,C5+1) | D6: =D5+1 | E6: 1 | F6: =TRUNC(((1+VLOOKUP(A6,IPCA!$A$2:$C$140,3,0)))^(C6/30),8) | G6: =TRUNC((E6*F6),8) | H6: =ROUND(((1+$H$4)^(30/360))^(C6/30),9) | I6: =TRUNC((G6*H6-G6),8) | J6: =G6+I6 | K6: Cri Integralizado | L6: 1113210
A7: =IF(DAY(D7)=DAY($L$1+1),A6+1,A6) | B7: =IF(DAY(D7)=DAY($L$1+1),1,B6+1) | C7: =IF(DAY(D7)=DAY($L$1+1),1,C6+1) | D7: =D6+1 | E7: =IF(DAY(D7)=DAY($L$1+1),TRUNC((N6),8),E6) | F7: =TRUNC(((1+VLOOKUP(A7,IPCA!$A$2:$C$140,3,0)))^(C7/30),8) | G7: =TRUNC((E7*F7),8) | H7: =ROUND(((1+$H$4)^(30/360))^(C7/30),9) | I7: =TRUNC((G7*H7-G7),8) | J7: =G7+I7
A8: =IF(DAY(D8)=DAY($L$1+1),A7+1,A7) | B8: =IF(DAY(D8)=DAY($L$1+1),1,B7+1) | C8: =IF(DAY(D8)=DAY($L$1+1),1,C7+1) | D8: =D7+1 | E8: =IF(DAY(D8)=DAY($L$1+1),TRUNC((N7),8),E7) | F8: =TRUNC(((1+VLOOKUP(A8,IPCA!$A$2:$C$140,3,0)))^(C8/30),8) | G8: =TRUNC((E8*F8),8) | H8: =ROUND(((1+$H$4)^(30/360))^(C8/30),9) | I8: =TRUNC((G8*H8-G8),8) | J8: =G8+I8
A9: =IF(DAY(D9)=DAY($L$1+1),A8+1,A8) | B9: =IF(DAY(D9)=DAY($L$1+1),1,B8+1) | C9: =IF(DAY(D9)=DAY($L$1+1),1,C8+1) | D9: =D8+1 | E9: =IF(DAY(D9)=DAY($L$1+1),TRUNC((N8),8),E8) | F9: =TRUNC(((1+VLOOKUP(A9,IPCA!$A$2:$C$140,3,0)))^(C9/30),8) | G9: =TRUNC((E9*F9),8) | H9: =ROUND(((1+$H$4)^(30/360))^(C9/30),9) | I9: =TRUNC((G9*H9-G9),8) | J9: =G9+I9
A10: =IF(DAY(D10)=DAY($L$1+1),A9+1,A9) | B10: =IF(DAY(D10)=DAY($L$1+1),1,B9+1) | C10: =IF(DAY(D10)=DAY($L$1+1),1,C9+1) | D10: =D9+1 | E10: =IF(DAY(D10)=DAY($L$1+1),TRUNC((N9),8),E9) | F10: =TRUNC(((1+VLOOKUP(A10,IPCA!$A$2:$C$140,3,0)))^(C10/30),8) | G10: =TRUNC((E10*F10),8) | H10: =ROUND(((1+$H$4)^(30/360))^(C10/30),9) | I10: =TRUNC((G10*H10-G10),8) | J10: =G10+I10
A11: =IF(DAY(D11)=DAY($L$1+1),A10+1,A10) | B11: =IF(DAY(D11)=DAY($L$1+1),1,B10+1) | C11: =IF(DAY(D11)=DAY($L$1+1),1,C10+1) | D11: =D10+1 | E11: =IF(DAY(D11)=DAY($L$1+1),TRUNC((N10),8),E10) | F11: =TRUNC(((1+VLOOKUP(A11,IPCA!$A$2:$C$140,3,0)))^(C11/30),8) | G11: =TRUNC((E11*F11),8) | H11: =ROUND(((1+$H$4)^(30/360))^(C11/30),9) | I11: =TRUNC((G11*H11-G11),8) | J11: =G11+I11
A12: =IF(DAY(D12)=DAY($L$1+1),A11+1,A11) | B12: =IF(DAY(D12)=DAY($L$1+1),1,B11+1) | C12: =IF(DAY(D12)=DAY($L$1+1),1,C11+1) | D12: =D11+1 | E12: =IF(DAY(D12)=DAY($L$1+1),TRUNC((N11),8),E11) | F12: =TRUNC(((1+VLOOKUP(A12,IPCA!$A$2:$C$140,3,0)))^(C12/30),8) | G12: =TRUNC((E12*F12),8) | H12: =ROUND(((1+$H$4)^(30/360))^(C12/30),9) | I12: =TRUNC((G12*H12-G12),8) | J12: =G12+I12 | K12: Cri Integralizado | L12: 668088
A13: =IF(DAY(D13)=DAY($L$1+1),A12+1,A12) | B13: =IF(DAY(D13)=DAY($L$1+1),1,B12+1) | C13: =IF(DAY(D13)=DAY($L$1+1),1,C12+1) | D13: =D12+1 | E13: =IF(DAY(D13)=DAY($L$1+1),TRUNC((N12),8),E12) | F13: =TRUNC(((1+VLOOKUP(A13,IPCA!$A$2:$C$140,3,0)))^(C13/30),8) | G13: =TRUNC((E13*F13),8) | H13: =ROUND(((1+$H$4)^(30/360))^(C13/30),9) | I13: =TRUNC((G13*H13-G13),8) | J13: =G13+I13
A14: =IF(DAY(D14)=DAY($L$1+1),A13+1,A13) | B14: =IF(DAY(D14)=DAY($L$1+1),1,B13+1) | C14: =IF(DAY(D14)=DAY($L$1+1),1,C13+1) | D14: =D13+1 | E14: =IF(DAY(D14)=DAY($L$1+1),TRUNC((N13),8),E13) | F14: =TRUNC(((1+VLOOKUP(A14,IPCA!$A$2:$C$140,3,0)))^(C14/30),8) | G14: =TRUNC((E14*F14),8) | H14: =ROUND(((1+$H$4)^(30/360))^(C14/30),9) | I14: =TRUNC((G14*H14-G14),8) | J14: =G14+I14
A15: =IF(DAY(D15)=DAY($L$1+1),A14+1,A14) | B15: =IF(DAY(D15)=DAY($L$1+1),1,B14+1) | C15: =IF(DAY(D15)=DAY($L$1+1),1,C14+1) | D15: =D14+1 | E15: =IF(DAY(D15)=DAY($L$1+1),TRUNC((N14),8),E14) | F15: =TRUNC(((1+VLOOKUP(A15,IPCA!$A$2:$C$140,3,0)))^(C15/30),8) | G15: =TRUNC((E15*F15),8) | H15: =ROUND(((1+$H$4)^(30/360))^(C15/30),9) | I15: =TRUNC((G15*H15-G15),8) | J15: =G15+I15
A16: =IF(DAY(D16)=DAY($L$1+1),A15+1,A15) | B16: =IF(DAY(D16)=DAY($L$1+1),1,B15+1) | C16: =IF(DAY(D16)=DAY($L$1+1),1,C15+1) | D16: =D15+1 | E16: =IF(DAY(D16)=DAY($L$1+1),TRUNC((N15),8),E15) | F16: =TRUNC(((1+VLOOKUP(A16,IPCA!$A$2:$C$140,3,0)))^(C16/30),8) | G16: =TRUNC((E16*F16),8) | H16: =ROUND(((1+$H$4)^(30/360))^(C16/30),9) | I16: =TRUNC((G16*H16-G16),8) | J16: =G16+I16
A17: =IF(DAY(D17)=DAY($L$1+1),A16+1,A16) | B17: =IF(DAY(D17)=DAY($L$1+1),1,B16+1) | C17: =IF(DAY(D17)=DAY($L$1+1),1,C16+1) | D17: =D16+1 | E17: =IF(DAY(D17)=DAY($L$1+1),TRUNC((N16),8),E16) | F17: =TRUNC(((1+VLOOKUP(A17,IPCA!$A$2:$C$140,3,0)))^(C17/30),8) | G17: =TRUNC((E17*F17),8) | H17: =ROUND(((1+$H$4)^(30/360))^(C17/30),9) | I17: =TRUNC((G17*H17-G17),8) | J17: =G17+I17 | K17: Cri Integralizado | L17: =1113210+L12
A18: =IF(DAY(D18)=DAY($L$1+1),A17+1,A17) | B18: =IF(DAY(D18)=DAY($L$1+1),1,B17+1) | C18: =IF(DAY(D18)=DAY($L$1+1),1,C17+1) | D18: =D17+1 | E18: =IF(DAY(D18)=DAY($L$1+1),TRUNC((N17),8),E17) | F18: =TRUNC(((1+VLOOKUP(A18,IPCA!$A$2:$C$140,3,0)))^(C18/30),8) | G18: =TRUNC((E18*F18),8) | H18: =ROUND(((1+$H$4)^(30/360))^(C18/30),9) | I18: =TRUNC((G18*H18-G18),8) | J18: =G18+I18 | K18: JUROS | L18: AMORTIZAÇÃO | M18: AMEX | N18: RESIDUAL
A19: =IF(DAY(D19)=DAY($L$1+1),A18+1,A18) | B19: =IF(DAY(D19)=DAY($L$1+1),1,B18+1) | C19: =IF(DAY(D19)=DAY($L$1+1),1,C18+1) | D19: =D18+1 | E19: =IF(DAY(D19)=DAY($L$1+1),TRUNC((N18),8),E18) | F19: =TRUNC(((1+VLOOKUP(A19,IPCA!$A$2:$C$140,3,0)))^(C19/30),8) | G19: =TRUNC((E19*F19),8) | H19: =ROUND(((1+$H$4)^(30/360))^(C19/30),9) | I19: =TRUNC((G19*H19-G19),8) | J19: =G19+I19 | K19: 0 | L19: 0 | M19: 0 | N19: 1100000
A20: =IF(DAY(D20)=DAY($L$1+1),A19+1,A19) | B20: =IF(DAY(D20)=DAY($L$1+1),1,B19+1) | C20: =IF(DAY(D20)=DAY($L$1+1),1,C19+1) | D20: =D19+1 | E20: =IF(DAY(D20)=DAY($L$1+1),TRUNC((N19),8),E19) | F20: =TRUNC(((1+VLOOKUP(A20,IPCA!$A$2:$C$140,3,0)))^(C20/(EDATE(D20-C20,1)-(D20-C20))),8) | G20: =TRUNC((E20*F20),8) | H20: =ROUND(((1+$H$4)^(30/360))^(C20/(EDATE(D20-B20,1)-(D20-B20))),9) | I20: =TRUNC((G20*H20-G20),8) | J20: =G20+I20 | K20: =K19*L17 | L20: =L19*L17 | M20: =M19*L17 | N20: =N19*L17
A21: =IF(DAY(D21)=DAY($L$1+1),A20+1,A20) | B21: =IF(DAY(D21)=DAY($L$1+1),1,B20+1) | C21: =IF(DAY(D21)=DAY($L$1+1),1,C20+1) | D21: =D20+1 | E21: =IF(DAY(D21)=DAY($L$1+1),TRUNC((N20),8),E20) | F21: =TRUNC(((1+VLOOKUP(A21,IPCA!$A$2:$C$140,3,0)))^(C21/(EDATE(D21-C21,1)-(D21-C21))),8) | G21: =TRUNC((E21*F21),8) | H21: =ROUND(((1+$H$4)^(30/360))^(C21/(EDATE(D21-B21,1)-(D21-B21))),9) | I21: =TRUNC((G21*H21-G21),8) | J21: =G21+I21
A22: =IF(DAY(D22)=DAY($L$1+1),A21+1,A21) | B22: =IF(DAY(D22)=DAY($L$1+1),1,B21+1) | C22: =IF(DAY(D22)=DAY($L$1+1),1,C21+1) | D22: =D21+1 | E22: =IF(DAY(D22)=DAY($L$1+1),TRUNC((#REF!),8),E21) | F22: =TRUNC(((1+VLOOKUP(A22,IPCA!$A$2:$C$140,3,0)))^(C22/(EDATE(D22-C22,1)-(D22-C22))),8) | G22: =TRUNC((E22*F22),8) | H22: =ROUND(((1+$H$4)^(30/360))^(C22/(EDATE(D22-B22,1)-(D22-B22))),9) | I22: =TRUNC((G22*H22-G22),8) | J22: =G22+I22
A23: =IF(DAY(D23)=DAY($L$1+1),A22+1,A22) | B23: =IF(DAY(D23)=DAY($L$1+1),1,B22+1) | C23: =IF(DAY(D23)=DAY($L$1+1),1,C22+1) | D23: =D22+1 | E23: =IF(DAY(D23)=DAY($L$1+1),TRUNC((#REF!),8),E22) | F23: =TRUNC(((1+VLOOKUP(A23,IPCA!$A$2:$C$140,3,0)))^(C23/(EDATE(D23-C23,1)-(D23-C23))),8) | G23: =TRUNC((E23*F23),8) | H23: =ROUND(((1+$H$4)^(30/360))^(C23/(EDATE(D23-B23,1)-(D23-B23))),9) | I23: =TRUNC((G23*H23-G23),8) | J23: =G23+I23 | K23: 1.006196
A24: =IF(DAY(D24)=DAY($L$1+1),A23+1,A23) | B24: =IF(DAY(D24)=DAY($L$1+1),1,B23+1) | C24: =IF(DAY(D24)=DAY($L$1+1),1,C23+1) | D24: =D23+1 | E24: =IF(DAY(D24)=DAY($L$1+1),TRUNC((#REF!),8),E23) | F24: =TRUNC(((1+VLOOKUP(A24,IPCA!$A$2:$C$140,3,0)))^(C24/(EDATE(D24-C24,1)-(D24-C24))),8) | G24: =TRUNC((E24*F24),8) | H24: =ROUND(((1+$H$4)^(30/360))^(C24/(EDATE(D24-B24,1)-(D24-B24))),9) | I24: =TRUNC((G24*H24-G24),8) | J24: =G24+I24 | K24: =J20-K23
A25: =IF(DAY(D25)=DAY($L$1+1),A24+1,A24) | B25: =IF(DAY(D25)=DAY($L$1+1),1,B24+1) | C25: =IF(DAY(D25)=DAY($L$1+1),1,C24+1) | D25: =D24+1 | E25: =IF(DAY(D25)=DAY($L$1+1),TRUNC((#REF!),8),E24) | F25: =TRUNC(((1+VLOOKUP(A25,IPCA!$A$2:$C$140,3,0)))^(C25/(EDATE(D25-C25,1)-(D25-C25))),8) | G25: =TRUNC((E25*F25),8) | H25: =ROUND(((1+$H$4)^(30/360))^(C25/(EDATE(D25-B25,1)-(D25-B25))),9) | I25: =TRUNC((G25*H25-G25),8) | J25: =G25+I25
A26: =IF(DAY(D26)=DAY($L$1+1),A25+1,A25) | B26: =IF(DAY(D26)=DAY($L$1+1),1,B25+1) | C26: =IF(DAY(D26)=DAY($L$1+1),1,C25+1) | D26: =D25+1 | E26: =IF(DAY(D26)=DAY($L$1+1),TRUNC((#REF!),8),E25) | F26: =TRUNC(((1+VLOOKUP(A26,IPCA!$A$2:$C$140,3,0)))^(C26/(EDATE(D26-C26,1)-(D26-C26))),8) | G26: =TRUNC((E26*F26),8) | H26: =ROUND(((1+$H$4)^(30/360))^(C26/(EDATE(D26-B26,1)-(D26-B26))),9) | I26: =TRUNC((G26*H26-G26),8) | J26: =G26+I26
A27: =IF(DAY(D27)=DAY($L$1+1),A26+1,A26) | B27: =IF(DAY(D27)=DAY($L$1+1),1,B26+1) | C27: =IF(DAY(D27)=DAY($L$1+1),1,C26+1) | D27: =D26+1 | E27: =IF(DAY(D27)=DAY($L$1+1),TRUNC((#REF!),8),E26) | F27: =TRUNC(((1+VLOOKUP(A27,IPCA!$A$2:$C$140,3,0)))^(C27/(EDATE(D27-C27,1)-(D27-C27))),8) | G27: =TRUNC((E27*F27),8) | H27: =ROUND(((1+$H$4)^(30/360))^(C27/(EDATE(D27-B27,1)-(D27-B27))),9) | I27: =TRUNC((G27*H27-G27),8) | J27: =G27+I27
A28: =IF(DAY(D28)=DAY($L$1+1),A27+1,A27) | B28: =IF(DAY(D28)=DAY($L$1+1),1,B27+1) | C28: =IF(DAY(D28)=DAY($L$1+1),1,C27+1) | D28: =D27+1 | E28: =IF(DAY(D28)=DAY($L$1+1),TRUNC((#REF!),8),E27) | F28: =TRUNC(((1+VLOOKUP(A28,IPCA!$A$2:$C$140,3,0)))^(C28/(EDATE(D28-C28,1)-(D28-C28))),8) | G28: =TRUNC((E28*F28),8) | H28: =ROUND(((1+$H$4)^(30/360))^(C28/(EDATE(D28-B28,1)-(D28-B28))),9) | I28: =TRUNC((G28*H28-G28),8) | J28: =G28+I28
A29: =IF(DAY(D29)=DAY($L$1+1),A28+1,A28) | B29: =IF(DAY(D29)=DAY($L$1+1),1,B28+1) | C29: =IF(DAY(D29)=DAY($L$1+1),1,C28+1) | D29: =D28+1 | E29: =IF(DAY(D29)=DAY($L$1+1),TRUNC((#REF!),8),E28) | F29: =TRUNC(((1+VLOOKUP(A29,IPCA!$A$2:$C$140,3,0)))^(C29/(EDATE(D29-C29,1)-(D29-C29))),8) | G29: =TRUNC((E29*F29),8) | H29: =ROUND(((1+$H$4)^(30/360))^(C29/(EDATE(D29-B29,1)-(D29-B29))),9) | I29: =TRUNC((G29*H29-G29),8) | J29: =G29+I29
A30: =IF(DAY(D30)=DAY($L$1+1),A29+1,A29) | B30: =IF(DAY(D30)=DAY($L$1+1),1,B29+1) | C30: =IF(DAY(D30)=DAY($L$1+1),1,C29+1) | D30: =D29+1 | E30: =IF(DAY(D30)=DAY($L$1+1),TRUNC((#REF!),8),E29) | F30: =TRUNC(((1+VLOOKUP(A30,IPCA!$A$2:$C$140,3,0)))^(C30/(EDATE(D30-C30,1)-(D30-C30))),8) | G30: =TRUNC((E30*F30),8) | H30: =ROUND(((1+$H$4)^(30/360))^(C30/(EDATE(D30-B30,1)-(D30-B30))),9) | I30: =TRUNC((G30*H30-G30),8) | J30: =G30+I30
A31: =IF(DAY(D31)=DAY($L$1+1),A30+1,A30) | B31: =IF(DAY(D31)=DAY($L$1+1),1,B30+1) | C31: =IF(DAY(D31)=DAY($L$1+1),1,C30+1) | D31: =D30+1 | E31: =IF(DAY(D31)=DAY($L$1+1),TRUNC((N30),8),E30) | F31: =TRUNC(((1+VLOOKUP(A31,IPCA!$A$2:$C$140,3,0)))^(C31/(EDATE(D31-C31,1)-(D31-C31))),8) | G31: =TRUNC((E31*F31),8) | H31: =ROUND(((1+$H$4)^(30/360))^(C31/(EDATE(D31-B31,1)-(D31-B31))),9) | I31: =TRUNC((G31*H31-G31),8) | J31: =G31+I31
A32: =IF(DAY(D32)=DAY($L$1+1),A31+1,A31) | B32: =IF(DAY(D32)=DAY($L$1+1),1,B31+1) | C32: =IF(DAY(D32)=DAY($L$1+1),1,C31+1) | D32: =D31+1 | E32: =IF(DAY(D32)=DAY($L$1+1),TRUNC((N31),8),E31) | F32: =TRUNC(((1+VLOOKUP(A32,IPCA!$A$2:$C$140,3,0)))^(C32/(EDATE(D32-C32,1)-(D32-C32))),8) | G32: =TRUNC((E32*F32),8) | H32: =ROUND(((1+$H$4)^(30/360))^(C32/(EDATE(D32-B32,1)-(D32-B32))),9) | I32: =TRUNC((G32*H32-G32),8) | J32: =G32+I32
A33: =IF(DAY(D33)=DAY($L$1+1),A32+1,A32) | B33: =IF(DAY(D33)=DAY($L$1+1),1,B32+1) | C33: =IF(DAY(D33)=DAY($L$1+1),1,C32+1) | D33: =D32+1 | E33: =IF(DAY(D33)=DAY($L$1+1),TRUNC((N32),8),E32) | F33: =TRUNC(((1+VLOOKUP(A33,IPCA!$A$2:$C$140,3,0)))^(C33/(EDATE(D33-C33,1)-(D33-C33))),8) | G33: =TRUNC((E33*F33),8) | H33: =ROUND(((1+$H$4)^(30/360))^(C33/(EDATE(D33-B33,1)-(D33-B33))),9) | I33: =TRUNC((G33*H33-G33),8) | J33: =G33+I33
A34: =IF(DAY(D34)=DAY($L$1+1),A33+1,A33) | B34: =IF(DAY(D34)=DAY($L$1+1),1,B33+1) | C34: =IF(DAY(D34)=DAY($L$1+1),1,C33+1) | D34: =D33+1 | E34: =IF(DAY(D34)=DAY($L$1+1),TRUNC((N33),8),E33) | F34: =TRUNC(((1+VLOOKUP(A34,IPCA!$A$2:$C$140,3,0)))^(C34/(EDATE(D34-C34,1)-(D34-C34))),8) | G34: =TRUNC((E34*F34),8) | H34: =ROUND(((1+$H$4)^(30/360))^(C34/(EDATE(D34-B34,1)-(D34-B34))),9) | I34: =TRUNC((G34*H34-G34),8) | J34: =G34+I34
A35: =IF(DAY(D35)=DAY($L$1+1),A34+1,A34) | B35: =IF(DAY(D35)=DAY($L$1+1),1,B34+1) | C35: =IF(DAY(D35)=DAY($L$1+1),1,C34+1) | D35: =D34+1 | E35: =IF(DAY(D35)=DAY($L$1+1),TRUNC((N34),8),E34) | F35: =TRUNC(((1+VLOOKUP(A35,IPCA!$A$2:$C$140,3,0)))^(C35/(EDATE(D35-C35,1)-(D35-C35))),8) | G35: =TRUNC((E35*F35),8) | H35: =ROUND(((1+$H$4)^(30/360))^(C35/(EDATE(D35-B35,1)-(D35-B35))),9) | I35: =TRUNC((G35*H35-G35),8) | J35: =G35+I35
A36: =IF(DAY(D36)=DAY($L$1+1),A35+1,A35) | B36: =IF(DAY(D36)=DAY($L$1+1),1,B35+1) | C36: =IF(DAY(D36)=DAY($L$1+1),1,C35+1) | D36: =D35+1 | E36: =IF(DAY(D36)=DAY($L$1+1),TRUNC((N35),8),E35) | F36: =TRUNC(((1+VLOOKUP(A36,IPCA!$A$2:$C$140,3,0)))^(C36/(EDATE(D36-C36,1)-(D36-C36))),8) | G36: =TRUNC((E36*F36),8) | H36: =ROUND(((1+$H$4)^(30/360))^(C36/(EDATE(D36-B36,1)-(D36-B36))),9) | I36: =TRUNC((G36*H36-G36),8) | J36: =G36+I36
A37: =IF(DAY(D37)=DAY($L$1+1),A36+1,A36) | B37: =IF(DAY(D37)=DAY($L$1+1),1,B36+1) | C37: =IF(DAY(D37)=DAY($L$1+1),1,C36+1) | D37: =D36+1 | E37: =IF(DAY(D37)=DAY($L$1+1),TRUNC((N36),8),E36) | F37: =TRUNC(((1+VLOOKUP(A37,IPCA!$A$2:$C$140,3,0)))^(C37/(EDATE(D37-C37,1)-(D37-C37))),8) | G37: =TRUNC((E37*F37),8) | H37: =ROUND(((1+$H$4)^(30/360))^(C37/(EDATE(D37-B37,1)-(D37-B37))),9) | I37: =TRUNC((G37*H37-G37),8) | J37: =G37+I37
A38: =IF(DAY(D38)=DAY($L$1+1),A37+1,A37) | B38: =IF(DAY(D38)=DAY($L$1+1),1,B37+1) | C38: =IF(DAY(D38)=DAY($L$1+1),1,C37+1) | D38: =D37+1 | E38: =IF(DAY(D38)=DAY($L$1+1),TRUNC((N37),8),E37) | F38: =TRUNC(((1+VLOOKUP(A38,IPCA!$A$2:$C$140,3,0)))^(C38/(EDATE(D38-C38,1)-(D38-C38))),8) | G38: =TRUNC((E38*F38),8) | H38: =ROUND(((1+$H$4)^(30/360))^(C38/(EDATE(D38-B38,1)-(D38-B38))),9) | I38: =TRUNC((G38*H38-G38),8) | J38: =G38+I38
A39: =IF(DAY(D39)=DAY($L$1+1),A38+1,A38) | B39: =IF(DAY(D39)=DAY($L$1+1),1,B38+1) | C39: =IF(DAY(D39)=DAY($L$1+1),1,C38+1) | D39: =D38+1 | E39: =IF(DAY(D39)=DAY($L$1+1),TRUNC((N38),8),E38) | F39: =TRUNC(((1+VLOOKUP(A39,IPCA!$A$2:$C$140,3,0)))^(C39/(EDATE(D39-C39,1)-(D39-C39))),8) | G39: =TRUNC((E39*F39),8) | H39: =ROUND(((1+$H$4)^(30/360))^(C39/(EDATE(D39-B39,1)-(D39-B39))),9) | I39: =TRUNC((G39*H39-G39),8) | J39: =G39+I39
A40: =IF(DAY(D40)=DAY($L$1+1),A39+1,A39) | B40: =IF(DAY(D40)=DAY($L$1+1),1,B39+1) | C40: =IF(DAY(D40)=DAY($L$1+1),1,C39+1) | D40: =D39+1 | E40: =IF(DAY(D40)=DAY($L$1+1),TRUNC((N39),8),E39) | F40: =TRUNC(((1+VLOOKUP(A40,IPCA!$A$2:$C$140,3,0)))^(C40/(EDATE(D40-C40,1)-(D40-C40))),8) | G40: =TRUNC((E40*F40),8) | H40: =ROUND(((1+$H$4)^(30/360))^(C40/(EDATE(D40-B40,1)-(D40-B40))),9) | I40: =TRUNC((G40*H40-G40),8) | J40: =G40+I40
...

Sheet Amort TS
F1: TABELA DE AMORTIZAÇÃO DOS CRI
J2: DADOS DA PMT | Q2: CONTABILIDADE | R2: CORREÇÃO
C3: TRIMESTRE | D3: MÊS | E3: ANO | F3: Evento | G3: Data | H3: Amortização | J3: JUROS | K3: AMORTIZAÇÃO | L3: PMT | M3: AMEX | N3: PMT C/ AMEX | O3: CRI INTEGRALIZADO | P3: SALDO DEVEDOR (EVENTO) = AmorTs | Q3: SALDO DEVEDOR (ÚLTIMO DIA DO MÊS)
A4: =CONCATENATE(C4,D4,E4) | B4: =CONCATENATE(D4,E4) | C4: =IF(D4>=1,IF(D4<=3,"1",IF(D4>=4,IF(D4<=6,"2",IF(D4>=7,IF(D4<=9,"3",IF(D4>=10,IF(D4<=12,"4","-")))))))) | D4: =MONTH(G4) | E4: =YEAR(G4) | F4: 1 | G4: 44767 | H4: 0 | I4: 29 | J4: =IFERROR((VLOOKUP($G4,'22F1187231'!$D$3:$N$4160,8,1))*O4,0) | K4: =VLOOKUP(G4,'22F1187231'!$D$5:$L$4163,9,0)*O4 | L4: =SUM(J4:K4) | M4: =(VLOOKUP($G4,'22F1187231'!$D$5:$N$4163,10,1))*O4 | N4: =SUM(L4:M4) | O4: 1113210 | P4: =VLOOKUP(G4,'22F1187231'!$D$5:$J$4160,7,0)*O4-(SUM(J4:K4,M4)) | Q4: =(VLOOKUP(EOMONTH(G4,0),'22F1187231'!$D$5:$J$4160,7,0))*O4 | R4: =(VLOOKUP(G4,'22F1187231'!$D$5:$J$4160,4,0)-VLOOKUP(G4,'22F1187231'!$D$5:$J$4160,2,0))*O4 | T4: CVM / PENTAGONO
A5: =CONCATENATE(C5,D5,E5) | B5: =CONCATENATE(D5,E5) | C5: =IF(D5>=1,IF(D5<=3,"1",IF(D5>=4,IF(D5<=6,"2",IF(D5>=7,IF(D5<=9,"3",IF(D5>=10,IF(D5<=12,"4","-")))))))) | D5: =MONTH(G5) | E5: =YEAR(G5) | F5: =F4+1 | G5: 44798 | H5: 0 | I5: 30 | J5: =IFERROR((VLOOKUP($G5,'22F1187231'!$D$3:$N$4160,8,1))*O5,0) | K5: =VLOOKUP(G5,'22F1187231'!$D$5:$L$4163,9,0)*O5 | L5: =SUM(J5:K5) | M5: =(VLOOKUP($G5,'22F1187231'!$D$5:$N$4163,10,1))*O5 | N5: =SUM(L5:M5) | O5: 1113210 | P5: =VLOOKUP(G5,'22F1187231'!$D$5:$J$4160,7,0)*O5-(SUM(J5:K5,M5)) | Q5: =(VLOOKUP(EOMONTH(G5,0),'22F1187231'!$D$5:$J$4160,7,0))*O5 | R5: =(VLOOKUP(G5,'22F1187231'!$D$5:$J$4160,4,0)-VLOOKUP(G5,'22F1187231'!$D$5:$J$4160,2,0))*O5 | T5: SET/2023
A6: =CONCATENATE(C6,D6,E6) | B6: =CONCATENATE(D6,E6) | C6: =IF(D6>=1,IF(D6<=3,"1",IF(D6>=4,IF(D6<=6,"2",IF(D6>=7,IF(D6<=9,"3",IF(D6>=10,IF(D6<=12,"4","-")))))))) | D6: =MONTH(G6) | E6: =YEAR(G6) | F6: =F5+1 | G6: 44829 | H6: 0 | I6: 31 | J6: =IFERROR((VLOOKUP($G6,'22F1187231'!$D$3:$N$4160,8,1))*O6,0) | K6: =VLOOKUP(G6,'22F1187231'!$D$5:$L$4163,9,0)*O6 | L6: =SUM(J6:K6) | M6: =(VLOOKUP($G6,'22F1187231'!$D$5:$N$4163,10,1))*O6 | N6: =SUM(L6:M6) | O6: 1113210 | P6: =VLOOKUP(G6,'22F1187231'!$D$5:$J$4160,7,0)*O6-(SUM(J6:K6,M6)) | Q6: =(VLOOKUP(EOMONTH(G6,0),'22F1187231'!$D$5:$J$4160,7,0))*O6 | R6: =(VLOOKUP(G6,'22F1187231'!$D$5:$J$4160,4,0)-VLOOKUP(G6,'22F1187231'!$D$5:$J$4160,2,0))*O6 | T6: Circulante: | U6: =SUM(N18:N29)
A7: =CONCATENATE(C7,D7,E7) | B7: =CONCATENATE(D7,E7) | C7: =IF(D7>=1,IF(D7<=3,"1",IF(D7>=4,IF(D7<=6,"2",IF(D7>=7,IF(D7<=9,"3",IF(D7>=10,IF(D7<=12,"4","-")))))))) | D7: =MONTH(G7) | E7: =YEAR(G7) | F7: =F6+1 | G7: 44859 | H7: 0 | I7: 32 | J7: =IFERROR((VLOOKUP($G7,'22F1187231'!$D$3:$N$4160,8,1))*O7,0) | K7: =VLOOKUP(G7,'22F1187231'!$D$5:$L$4163,9,0)*O7 | L7: =SUM(J7:K7) | M7: =(VLOOKUP($G7,'22F1187231'!$D$5:$N$4163,10,1))*O7 | N7: =SUM(L7:M7) | O7: 1113210 | P7: =VLOOKUP(G7,'22F1187231'!$D$5:$J$4160,7,0)*O7-(SUM(J7:K7,M7)) | Q7: =(VLOOKUP(EOMONTH(G7,0),'22F1187231'!$D$5:$J$4160,7,0))*O7 | R7: =(VLOOKUP(G7,'22F1187231'!$D$5:$J$4160,4,0)-VLOOKUP(G7,'22F1187231'!$D$5:$J$4160,2,0))*O7 | T7: Não Circulante: | U7: =P17-U6
A8: =CONCATENATE(C8,D8,E8) | B8: =CONCATENATE(D8,E8) | C8: =IF(D8>=1,IF(D8<=3,"1",IF(D8>=4,IF(D8<=6,"2",IF(D8>=7,IF(D8<=9,"3",IF(D8>=10,IF(D8<=12,"4","-")))))))) | D8: =MONTH(G8) | E8: =YEAR(G8) | F8: =F7+1 | G8: 44890 | H8: 0 | I8: 33 | J8: =IFERROR((VLOOKUP($G8,'22F1187231'!$D$3:$N$4160,8,1))*O8,0) | K8: =VLOOKUP(G8,'22F1187231'!$D$5:$L$4163,9,0)*O8 | L8: =SUM(J8:K8) | M8: =(VLOOKUP($G8,'22F1187231'!$D$5:$N$4163,10,1))*O8 | N8: =SUM(L8:M8) | O8: 1113210 | P8: =VLOOKUP(G8,'22F1187231'!$D$5:$J$4160,7,0)*O8-(SUM(J8:K8,M8)) | Q8: =(VLOOKUP(EOMONTH(G8,0),'22F1187231'!$D$5:$J$4160,7,0))*O8 | R8: =(VLOOKUP(G8,'22F1187231'!$D$5:$J$4160,4,0)-VLOOKUP(G8,'22F1187231'!$D$5:$J$4160,2,0))*O8
A9: =CONCATENATE(C9,D9,E9) | B9: =CONCATENATE(D9,E9) | C9: =IF(D9>=1,IF(D9<=3,"1",IF(D9>=4,IF(D9<=6,"2",IF(D9>=7,IF(D9<=9,"3",IF(D9>=10,IF(D9<=12,"4","-")))))))) | D9: =MONTH(G9) | E9: =YEAR(G9) | F9: =F8+1 | G9: 44920 | H9: 0 | I9: 34 | J9: =IFERROR((VLOOKUP($G9,'22F1187231'!$D$3:$N$4160,8,1))*O9,0) | K9: =VLOOKUP(G9,'22F1187231'!$D$5:$L$4163,9,0)*O9 | L9: =SUM(J9:K9) | M9: =(VLOOKUP($G9,'22F1187231'!$D$5:$N$4163,10,1))*O9 | N9: =SUM(L9:M9) | O9: 1113210 | P9: =VLOOKUP(G9,'22F1187231'!$D$5:$J$4160,7,0)*O9-(SUM(J9:K9,M9)) | Q9: =(VLOOKUP(EOMONTH(G9,0),'22F1187231'!$D$5:$J$4160,7,0))*O9 | R9: =(VLOOKUP(G9,'22F1187231'!$D$5:$J$4160,4,0)-VLOOKUP(G9,'22F1187231'!$D$5:$J$4160,2,0))*O9
A10: =CONCATENATE(C10,D10,E10) | B10: =CONCATENATE(D10,E10) | C10: =IF(D10>=1,IF(D10<=3,"1",IF(D10>=4,IF(D10<=6,"2",IF(D10>=7,IF(D10<=9,"3",IF(D10>=10,IF(D10<=12,"4","-")))))))) | D10: =MONTH(G10) | E10: =YEAR(G10) | F10: =F9+1 | G10: 44951 | H10: 0 | I10: 35 | J10: =IFERROR((VLOOKUP($G10,'22F1187231'!$D$3:$N$4160,8,1))*O10,0) | K10: =VLOOKUP(G10,'22F1187231'!$D$5:$L$4163,9,0)*O10 | L10: =SUM(J10:K10) | M10: =(VLOOKUP($G10,'22F1187231'!$D$5:$N$4163,10,1))*O10 | N10: =SUM(L10:M10) | O10: 1113210 | P10: =VLOOKUP(G10,'22F1187231'!$D$5:$J$4160,7,0)*O10-(SUM(J10:K10,M10)) | Q10: =(VLOOKUP(EOMONTH(G10,0),'22F1187231'!$D$5:$J$4160,7,0))*O10 | R10: =(VLOOKUP(G10,'22F1187231'!$D$5:$J$4160,4,0)-VLOOKUP(G10,'22F1187231'!$D$5:$J$4160,2,0))*O10 | T10: CONFERÊNCIA
A11: =CONCATENATE(C11,D11,E11) | B11: =CONCATENATE(D11,E11) | C11: =IF(D11>=1,IF(D11<=3,"1",IF(D11>=4,IF(D11<=6,"2",IF(D11>=7,IF(D11<=9,"3",IF(D11>=10,IF(D11<=12,"4","-")))))))) | D11: =MONTH(G11) | E11: =YEAR(G11) | F11: =F10+1 | G11: 44982 | H11: 0 | I11: 36 | J11: =IFERROR((VLOOKUP($G11,'22F1187231'!$D$3:$N$4160,8,1))*O11,0) | K11: =VLOOKUP(G11,'22F1187231'!$D$5:$L$4163,9,0)*O11 | L11: =SUM(J11:K11) | M11: =(VLOOKUP($G11,'22F1187231'!$D$5:$N$4163,10,1))*O11 | N11: =SUM(L11:M11) | O11: 1113210 | P11: =VLOOKUP(G11,'22F1187231'!$D$5:$J$4160,7,0)*O11-(SUM(J11:K11,M11)) | Q11: =(VLOOKUP(EOMONTH(G11,0),'22F1187231'!$D$5:$J$4160,7,0))*O11 | R11: =(VLOOKUP(G11,'22F1187231'!$D$5:$J$4160,4,0)-VLOOKUP(G11,'22F1187231'!$D$5:$J$4160,2,0))*O11 | T11: PAGAMENTO | U11: INICIO PERIODO | V11: FINAL PERÍODO | W11: BUSCAR SALDO DIA
A12: =CONCATENATE(C12,D12,E12) | B12: =CONCATENATE(D12,E12) | C12: =IF(D12>=1,IF(D12<=3,"1",IF(D12>=4,IF(D12<=6,"2",IF(D12>=7,IF(D12<=9,"3",IF(D12>=10,IF(D12<=12,"4","-")))))))) | D12: =MONTH(G12) | E12: =YEAR(G12) | F12: =F11+1 | G12: 45010 | H12: 0 | I12: 37 | J12: =IFERROR((VLOOKUP($G12,'22F1187231'!$D$3:$N$4160,8,1))*O12,0) | K12: =VLOOKUP(G12,'22F1187231'!$D$5:$L$4163,9,0)*O12 | L12: =SUM(J12:K12) | M12: =(VLOOKUP($G12,'22F1187231'!$D$5:$N$4163,10,1))*O12 | N12: =SUM(L12:M12) | O12: 1113210 | P12: =VLOOKUP(G12,'22F1187231'!$D$5:$J$4160,7,0)*O12-(SUM(J12:K12,M12)) | Q12: =(VLOOKUP(EOMONTH(G12,0),'22F1187231'!$D$5:$J$4160,7,0))*O12 | R12: =(VLOOKUP(G12,'22F1187231'!$D$5:$J$4160,4,0)-VLOOKUP(G12,'22F1187231'!$D$5:$J$4160,2,0))*O12 | U12: 44470 | V12: 44834 | W12: 44824
A13: =CONCATENATE(C13,D13,E13) | B13: =CONCATENATE(D13,E13) | C13: =IF(D13>=1,IF(D13<=3,"1",IF(D13>=4,IF(D13<=6,"2",IF(D13>=7,IF(D13<=9,"3",IF(D13>=10,IF(D13<=12,"4","-")))))))) | D13: =MONTH(G13) | E13: =YEAR(G13) | F13: =F12+1 | G13: 45041 | H13: 0 | I13: 38 | J13: =IFERROR((VLOOKUP($G13,'22F1187231'!$D$3:$N$4160,8,1))*O13,0) | K13: =VLOOKUP(G13,'22F1187231'!$D$5:$L$4163,9,0)*O13 | L13: =SUM(J13:K13) | M13: =(VLOOKUP($G13,'22F1187231'!$D$5:$N$4163,10,1))*O13 | N13: =SUM(L13:M13) | O13: 1113210 | P13: =VLOOKUP(G13,'22F1187231'!$D$5:$J$4160,7,0)*O13-(SUM(J13:K13,M13)) | Q13: =(VLOOKUP(EOMONTH(G13,0),'22F1187231'!$D$5:$J$4160,7,0))*O13 | R13: =(VLOOKUP(G13,'22F1187231'!$D$5:$J$4160,4,0)-VLOOKUP(G13,'22F1187231'!$D$5:$J$4160,2,0))*O13 | T13: Juros | U13: =SUMIFS(J:J,G:G,">="&$U$12,G:G,"<="&$V$12)
A14: =CONCATENATE(C14,D14,E14) | B14: =CONCATENATE(D14,E14) | C14: =IF(D14>=1,IF(D14<=3,"1",IF(D14>=4,IF(D14<=6,"2",IF(D14>=7,IF(D14<=9,"3",IF(D14>=10,IF(D14<=12,"4","-")))))))) | D14: =MONTH(G14) | E14: =YEAR(G14) | F14: =F13+1 | G14: 45071 | H14: 0 | I14: 39 | J14: =IFERROR((VLOOKUP($G14,'22F1187231'!$D$3:$N$4160,8,1))*O14,0) | K14: =VLOOKUP(G14,'22F1187231'!$D$5:$L$4163,9,0)*O14 | L14: =SUM(J14:K14) | M14: =(VLOOKUP($G14,'22F1187231'!$D$5:$N$4163,10,1))*O14 | N14: =SUM(L14:M14) | O14: 1113210 | P14: =VLOOKUP(G14,'22F1187231'!$D$5:$J$4160,7,0)*O14-(SUM(J14:K14,M14)) | Q14: =(VLOOKUP(EOMONTH(G14,0),'22F1187231'!$D$5:$J$4160,7,0))*O14 | R14: =(VLOOKUP(G14,'22F1187231'!$D$5:$J$4160,4,0)-VLOOKUP(G14,'22F1187231'!$D$5:$J$4160,2,0))*O14 | T14: Amortização | U14: =SUMIFS(K:K,G:G,">="&$U$12,G:G,"<="&$V$12)
A15: =CONCATENATE(C15,D15,E15) | B15: =CONCATENATE(D15,E15) | C15: =IF(D15>=1,IF(D15<=3,"1",IF(D15>=4,IF(D15<=6,"2",IF(D15>=7,IF(D15<=9,"3",IF(D15>=10,IF(D15<=12,"4","-")))))))) | D15: =MONTH(G15) | E15: =YEAR(G15) | F15: =F14+1 | G15: 45102 | H15: 0 | I15: 40 | J15: =IFERROR((VLOOKUP($G15,'22F1187231'!$D$3:$N$4160,8,1))*O15,0) | K15: =VLOOKUP(G15,'22F1187231'!$D$5:$L$4163,9,0)*O15 | L15: =SUM(J15:K15) | M15: =(VLOOKUP($G15,'22F1187231'!$D$5:$N$4163,10,1))*O15 | N15: =SUM(L15:M15) | O15: 1113210 | P15: =VLOOKUP(G15,'22F1187231'!$D$5:$J$4160,7,0)*O15-(SUM(J15:K15,M15)) | Q15: =(VLOOKUP(EOMONTH(G15,0),'22F1187231'!$D$5:$J$4160,7,0))*O15 | R15: =(VLOOKUP(G15,'22F1187231'!$D$5:$J$4160,4,0)-VLOOKUP(G15,'22F1187231'!$D$5:$J$4160,2,0))*O15 | T15: Amex | U15: =SUMIFS(M:M,G:G,">="&$U$12,G:G,"<="&$V$12)
A16: =CONCATENATE(C16,D16,E16) | B16: =CONCATENATE(D16,E16) | C16: =IF(D16>=1,IF(D16<=3,"1",IF(D16>=4,IF(D16<=6,"2",IF(D16>=7,IF(D16<=9,"3",IF(D16>=10,IF(D16<=12,"4","-")))))))) | D16: =MONTH(G16) | E16: =YEAR(G16) | F16: =F15+1 | G16: 45132 | H16: 0.004083 | I16: 41 | J16: =IFERROR((VLOOKUP($G16,'22F1187231'!$D$3:$N$4160,8,1))*O16,0) | K16: =VLOOKUP(G16,'22F1187231'!$D$5:$L$4163,9,0)*O16 | L16: =SUM(J16:K16) | M16: =(VLOOKUP($G16,'22F1187231'!$D$5:$N$4163,10,1))*O16 | N16: =SUM(L16:M16) | O16: 1113210 | P16: =VLOOKUP(G16,'22F1187231'!$D$5:$J$4160,7,0)*O16-(SUM(J16:K16,M16)) | Q16: =(VLOOKUP(EOMONTH(G16,0),'22F1187231'!$D$5:$J$4160,7,0))*O16 | R16: =(VLOOKUP(G16,'22F1187231'!$D$5:$J$4160,4,0)-VLOOKUP(G16,'22F1187231'!$D$5:$J$4160,2,0))*O16 | T16: Correcao | U16: =SUMIFS(R:R,G:G,">="&$U$12,G:G,"<="&$V$12)
A17: =CONCATENATE(C17,D17,E17) | B17: =CONCATENATE(D17,E17) | C17: =IF(D17>=1,IF(D17<=3,"1",IF(D17>=4,IF(D17<=6,"2",IF(D17>=7,IF(D17<=9,"3",IF(D17>=10,IF(D17<=12,"4","-")))))))) | D17: =MONTH(G17) | E17: =YEAR(G17) | F17: =F16+1 | G17: 45163 | H17: 0.004123 | I17: 42 | J17: =IFERROR((VLOOKUP($G17,'22F1187231'!$D$3:$N$4160,8,1))*O17,0) | K17: =VLOOKUP(G17,'22F1187231'!$D$5:$L$4163,9,0)*O17 | L17: =SUM(J17:K17) | M17: =(VLOOKUP($G17,'22F1187231'!$D$5:$N$4163,10,1))*O17 | N17: =SUM(L17:M17) | O17: 1113210 | P17: =VLOOKUP(G17,'22F1187231'!$D$5:$J$4160,7,0)*O17-(SUM(J17:K17,M17)) | Q17: =(VLOOKUP(EOMONTH(G17,0),'22F1187231'!$D$5:$J$4160,7,0))*O17 | R17: =(VLOOKUP(G17,'22F1187231'!$D$5:$J$4160,4,0)-VLOOKUP(G17,'22F1187231'!$D$5:$J$4160,2,0))*O17 | T17: Saldo Operação | U17: ='22F1187231'!N82
A18: =CONCATENATE(C18,D18,E18) | B18: =CONCATENATE(D18,E18) | C18: =IF(D18>=1,IF(D18<=3,"1",IF(D18>=4,IF(D18<=6,"2",IF(D18>=7,IF(D18<=9,"3",IF(D18>=10,IF(D18<=12,"4","-")))))))) | D18: =MONTH(G18) | E18: =YEAR(G18) | F18: =F17+1 | G18: 45194 | H18: 0.004164 | I18: 43 | J18: =IFERROR((VLOOKUP($G18,'22F1187231'!$D$3:$N$4160,8,1))*O18,0) | K18: =VLOOKUP(G18,'22F1187231'!$D$5:$L$4163,9,0)*O18 | L18: =SUM(J18:K18) | M18: =(VLOOKUP($G18,'22F1187231'!$D$5:$N$4163,10,1))*O18 | N18: =SUM(L18:M18) | O18: 1113210 | P18: =VLOOKUP(G18,'22F1187231'!$D$5:$J$4160,7,0)*O18-(SUM(J18:K18,M18)) | Q18: =(VLOOKUP(EOMONTH(G18,0),'22F1187231'!$D$5:$J$4160,7,0))*O18 | R18: =(VLOOKUP(G18,'22F1187231'!$D$5:$J$4160,4,0)-VLOOKUP(G18,'22F1187231'!$D$5:$J$4160,2,0))*O18
A19: =CONCATENATE(C19,D19,E19) | B19: =CONCATENATE(D19,E19) | C19: =IF(D19>=1,IF(D19<=3,"1",IF(D19>=4,IF(D19<=6,"2",IF(D19>=7,IF(D19<=9,"3",IF(D19>=10,IF(D19<=12,"4","-")))))))) | D19: =MONTH(G19) | E19: =YEAR(G19) | F19: =F18+1 | G19: 45224 | H19: 0.004216 | I19: 44 | J19: =IFERROR((VLOOKUP($G19,'22F1187231'!$D$3:$N$4160,8,1))*O19,0) | K19: =VLOOKUP(G19,'22F1187231'!$D$5:$L$4163,9,0)*O19 | L19: =SUM(J19:K19) | M19: =(VLOOKUP($G19,'22F1187231'!$D$5:$N$4163,10,1))*O19 | N19: =SUM(L19:M19) | O19: 1113210 | P19: =VLOOKUP(G19,'22F1187231'!$D$5:$J$4160,7,0)*O19-(SUM(J19:K19,M19)) | Q19: =(VLOOKUP(EOMONTH(G19,0),'22F1187231'!$D$5:$J$4160,7,0))*O19 | R19: =(VLOOKUP(G19,'22F1187231'!$D$5:$J$4160,4,0)-VLOOKUP(G19,'22F1187231'!$D$5:$J$4160,2,0))*O19
A20: =CONCATENATE(C20,D20,E20) | B20: =CONCATENATE(D20,E20) | C20: =IF(D20>=1,IF(D20<=3,"1",IF(D20>=4,IF(D20<=6,"2",IF(D20>=7,IF(D20<=9,"3",IF(D20>=10,IF(D20<=12,"4","-")))))))) | D20: =MONTH(G20) | E20: =YEAR(G20) | F20: =F19+1 | G20: 45255 | H20: 0.004258 | I20: 45 | J20: =IFERROR((VLOOKUP($G20,'22F1187231'!$D$3:$N$4160,8,1))*O20,0) | K20: =VLOOKUP(G20,'22F1187231'!$D$5:$L$4163,9,0)*O20 | L20: =SUM(J20:K20) | M20: =(VLOOKUP($G20,'22F1187231'!$D$5:$N$4163,10,1))*O20 | N20: =SUM(L20:M20) | O20: 1113210 | P20: =VLOOKUP(G20,'22F1187231'!$D$5:$J$4160,7,0)*O20-(SUM(J20:K20,M20)) | Q20: =(VLOOKUP(EOMONTH(G20,0),'22F1187231'!$D$5:$J$4160,7,0))*O20 | R20: =(VLOOKUP(G20,'22F1187231'!$D$5:$J$4160,4,0)-VLOOKUP(G20,'22F1187231'!$D$5:$J$4160,2,0))*O20 | T20: Curto Prazo | U20: =SUM(N7:N18) | V20: Direitos Creditórios a Receber( Ativo/Passivo Circulante)
A21: =CONCATENATE(C21,D21,E21) | B21: =CONCATENATE(D21,E21) | C21: =IF(D21>=1,IF(D21<=3,"1",IF(D21>=4,IF(D21<=6,"2",IF(D21>=7,IF(D21<=9,"3",IF(D21>=10,IF(D21<=12,"4","-")))))))) | D21: =MONTH(G21) | E21: =YEAR(G21) | F21: =F20+1 | G21: 45285 | H21: 0.004388 | I21: 46 | J21: =IFERROR((VLOOKUP($G21,'22F1187231'!$D$3:$N$4160,8,1))*O21,0) | K21: =VLOOKUP(G21,'22F1187231'!$D$5:$L$4163,9,0)*O21 | L21: =SUM(J21:K21) | M21: =(VLOOKUP($G21,'22F1187231'!$D$5:$N$4163,10,1))*O21 | N21: =SUM(L21:M21) | O21: 1113210 | P21: =VLOOKUP(G21,'22F1187231'!$D$5:$J$4160,7,0)*O21-(SUM(J21:K21,M21)) | Q21: =(VLOOKUP(EOMONTH(G21,0),'22F1187231'!$D$5:$J$4160,7,0))*O21 | R21: =(VLOOKUP(G21,'22F1187231'!$D$5:$J$4160,4,0)-VLOOKUP(G21,'22F1187231'!$D$5:$J$4160,2,0))*O21 | T21: Longo Prazo | U21: =P6-U20 | V21: Direitos Creditórios a Receber( Ativo/Passivo Não Circulante)
A22: =CONCATENATE(C22,D22,E22) | B22: =CONCATENATE(D22,E22) | C22: =IF(D22>=1,IF(D22<=3,"1",IF(D22>=4,IF(D22<=6,"2",IF(D22>=7,IF(D22<=9,"3",IF(D22>=10,IF(D22<=12,"4","-")))))))) | D22: =MONTH(G22) | E22: =YEAR(G22) | F22: =F21+1 | G22: 45316 | H22: 0.004605 | I22: 47 | J22: =IFERROR((VLOOKUP($G22,'22F1187231'!$D$3:$N$4160,8,1))*O22,0) | K22: =VLOOKUP(G22,'22F1187231'!$D$5:$L$4163,9,0)*O22 | L22: =SUM(J22:K22) | M22: =(VLOOKUP($G22,'22F1187231'!$D$5:$N$4163,10,1))*O22 | N22: =SUM(L22:M22) | O22: 1113210 | P22: =VLOOKUP(G22,'22F1187231'!$D$5:$J$4160,7,0)*O22-(SUM(J22:K22,M22)) | Q22: =(VLOOKUP(EOMONTH(G22,0),'22F1187231'!$D$5:$J$4160,7,0))*O22 | R22: =(VLOOKUP(G22,'22F1187231'!$D$5:$J$4160,4,0)-VLOOKUP(G22,'22F1187231'!$D$5:$J$4160,2,0))*O22
A23: =CONCATENATE(C23,D23,E23) | B23: =CONCATENATE(D23,E23) | C23: =IF(D23>=1,IF(D23<=3,"1",IF(D23>=4,IF(D23<=6,"2",IF(D23>=7,IF(D23<=9,"3",IF(D23>=10,IF(D23<=12,"4","-")))))))) | D23: =MONTH(G23) | E23: =YEAR(G23) | F23: =F22+1 | G23: 45347 | H23: 0.004686 | I23: 48 | J23: =IFERROR((VLOOKUP($G23,'22F1187231'!$D$3:$N$4160,8,1))*O23,0) | K23: =VLOOKUP(G23,'22F1187231'!$D$5:$L$4163,9,0)*O23 | L23: =SUM(J23:K23) | M23: =(VLOOKUP($G23,'22F1187231'!$D$5:$N$4163,10,1))*O23 | N23: =SUM(L23:M23) | O23: 1113210 | P23: =VLOOKUP(G23,'22F1187231'!$D$5:$J$4160,7,0)*O23-(SUM(J23:K23,M23)) | Q23: =(VLOOKUP(EOMONTH(G23,0),'22F1187231'!$D$5:$J$4160,7,0))*O23 | R23: =(VLOOKUP(G23,'22F1187231'!$D$5:$J$4160,4,0)-VLOOKUP(G23,'22F1187231'!$D$5:$J$4160,2,0))*O23 | T23: PAGAMENTO | U23: Período (01/10/20 a 30/09/21)
A24: =CONCATENATE(C24,D24,E24) | B24: =CONCATENATE(D24,E24) | C24: =IF(D24>=1,IF(D24<=3,"1",IF(D24>=4,IF(D24<=6,"2",IF(D24>=7,IF(D24<=9,"3",IF(D24>=10,IF(D24<=12,"4","-")))))))) | D24: =MONTH(G24) | E24: =YEAR(G24) | F24: =F23+1 | G24: 45376 | H24: 0.004747 | I24: 49 | J24: =IFERROR((VLOOKUP($G24,'22F1187231'!$D$3:$N$4160,8,1))*O24,0) | K24: =VLOOKUP(G24,'22F1187231'!$D$5:$L$4163,9,0)*O24 | L24: =SUM(J24:K24) | M24: =(VLOOKUP($G24,'22F1187231'!$D$5:$N$4163,10,1))*O24 | N24: =SUM(L24:M24) | O24: 1113210 | P24: =VLOOKUP(G24,'22F1187231'!$D$5:$J$4160,7,0)*O24-(SUM(J24:K24,M24)) | Q24: =(VLOOKUP(EOMONTH(G24,0),'22F1187231'!$D$5:$J$4160,7,0))*O24 | R24: =(VLOOKUP(G24,'22F1187231'!$D$5:$J$4160,4,0)-VLOOKUP(G24,'22F1187231'!$D$5:$J$4160,2,0))*O24
A25: =CONCATENATE(C25,D25,E25) | B25: =CONCATENATE(D25,E25) | C25: =IF(D25>=1,IF(D25<=3,"1",IF(D25>=4,IF(D25<=6,"2",IF(D25>=7,IF(D25<=9,"3",IF(D25>=10,IF(D25<=12,"4","-")))))))) | D25: =MONTH(G25) | E25: =YEAR(G25) | F25: =F24+1 | G25: 45407 | H25: 0.004797 | I25: 50 | J25: =IFERROR((VLOOKUP($G25,'22F1187231'!$D$3:$N$4160,8,1))*O25,0) | K25: =VLOOKUP(G25,'22F1187231'!$D$5:$L$4163,9,0)*O25 | L25: =SUM(J25:K25) | M25: =(VLOOKUP($G25,'22F1187231'!$D$5:$N$4163,10,1))*O25 | N25: =SUM(L25:M25) | O25: 1113210 | P25: =VLOOKUP(G25,'22F1187231'!$D$5:$J$4160,7,0)*O25-(SUM(J25:K25,M25)) | Q25: =(VLOOKUP(EOMONTH(G25,0),'22F1187231'!$D$5:$J$4160,7,0))*O25 | R25: =(VLOOKUP(G25,'22F1187231'!$D$5:$J$4160,4,0)-VLOOKUP(G25,'22F1187231'!$D$5:$J$4160,2,0))*O25 | T25: Juros | U25: =SUM(J8:J19)
A26: =CONCATENATE(C26,D26,E26) | B26: =CONCATENATE(D26,E26) | C26: =IF(D26>=1,IF(D26<=3,"1",IF(D26>=4,IF(D26<=6,"2",IF(D26>=7,IF(D26<=9,"3",IF(D26>=10,IF(D26<=12,"4","-")))))))) | D26: =MONTH(G26) | E26: =YEAR(G26) | F26: =F25+1 | G26: 45437 | H26: 0.004847 | I26: 51 | J26: =IFERROR((VLOOKUP($G26,'22F1187231'!$D$3:$N$4160,8,1))*O26,0) | K26: =VLOOKUP(G26,'22F1187231'!$D$5:$L$4163,9,0)*O26 | L26: =SUM(J26:K26) | M26: =(VLOOKUP($G26,'22F1187231'!$D$5:$N$4163,10,1))*O26 | N26: =SUM(L26:M26) | O26: 1113210 | P26: =VLOOKUP(G26,'22F1187231'!$D$5:$J$4160,7,0)*O26-(SUM(J26:K26,M26)) | Q26: =(VLOOKUP(EOMONTH(G26,0),'22F1187231'!$D$5:$J$4160,7,0))*O26 | R26: =(VLOOKUP(G26,'22F1187231'!$D$5:$J$4160,4,0)-VLOOKUP(G26,'22F1187231'!$D$5:$J$4160,2,0))*O26 | T26: Amortização | U26: =SUM(K8:K19)
A27: =CONCATENATE(C27,D27,E27) | B27: =CONCATENATE(D27,E27) | C27: =IF(D27>=1,IF(D27<=3,"1",IF(D27>=4,IF(D27<=6,"2",IF(D27>=7,IF(D27<=9,"3",IF(D27>=10,IF(D27<=12,"4","-")))))))) | D27: =MONTH(G27) | E27: =YEAR(G27) | F27: =F26+1 | G27: 45468 | H27: 0.004899 | I27: 52 | J27: =IFERROR((VLOOKUP($G27,'22F1187231'!$D$3:$N$4160,8,1))*O27,0) | K27: =VLOOKUP(G27,'22F1187231'!$D$5:$L$4163,9,0)*O27 | L27: =SUM(J27:K27) | M27: =(VLOOKUP($G27,'22F1187231'!$D$5:$N$4163,10,1))*O27 | N27: =SUM(L27:M27) | O27: 1113210 | P27: =VLOOKUP(G27,'22F1187231'!$D$5:$J$4160,7,0)*O27-(SUM(J27:K27,M27)) | Q27: =(VLOOKUP(EOMONTH(G27,0),'22F1187231'!$D$5:$J$4160,7,0))*O27 | R27: =(VLOOKUP(G27,'22F1187231'!$D$5:$J$4160,4,0)-VLOOKUP(G27,'22F1187231'!$D$5:$J$4160,2,0))*O27 | T27: Amex | U27: =SUM(M7:M18)
A28: =CONCATENATE(C28,D28,E28) | B28: =CONCATENATE(D28,E28) | C28: =IF(D28>=1,IF(D28<=3,"1",IF(D28>=4,IF(D28<=6,"2",IF(D28>=7,IF(D28<=9,"3",IF(D28>=10,IF(D28<=12,"4","-")))))))) | D28: =MONTH(G28) | E28: =YEAR(G28) | F28: =F27+1 | G28: 45498 | H28: 0.004951 | I28: 53 | J28: =IFERROR((VLOOKUP($G28,'22F1187231'!$D$3:$N$4160,8,1))*O28,0) | K28: =VLOOKUP(G28,'22F1187231'!$D$5:$L$4163,9,0)*O28 | L28: =SUM(J28:K28) | M28: =(VLOOKUP($G28,'22F1187231'!$D$5:$N$4163,10,1))*O28 | N28: =SUM(L28:M28) | O28: 1113210 | P28: =VLOOKUP(G28,'22F1187231'!$D$5:$J$4160,7,0)*O28-(SUM(J28:K28,M28)) | Q28: =(VLOOKUP(EOMONTH(G28,0),'22F1187231'!$D$5:$J$4160,7,0))*O28 | R28: =(VLOOKUP(G28,'22F1187231'!$D$5:$J$4160,4,0)-VLOOKUP(G28,'22F1187231'!$D$5:$J$4160,2,0))*O28 | T28: Amort + Amex | U28: =SUM(K8:K19)+SUM(M8:M19)
A29: =CONCATENATE(C29,D29,E29) | B29: =CONCATENATE(D29,E29) | C29: =IF(D29>=1,IF(D29<=3,"1",IF(D29>=4,IF(D29<=6,"2",IF(D29>=7,IF(D29<=9,"3",IF(D29>=10,IF(D29<=12,"4","-")))))))) | D29: =MONTH(G29) | E29: =YEAR(G29) | F29: =F28+1 | G29: 45529 | H29: 0.005003 | I29: 54 | J29: =IFERROR((VLOOKUP($G29,'22F1187231'!$D$3:$N$4160,8,1))*O29,0) | K29: =VLOOKUP(G29,'22F1187231'!$D$5:$L$4163,9,0)*O29 | L29: =SUM(J29:K29) | M29: =(VLOOKUP($G29,'22F1187231'!$D$5:$N$4163,10,1))*O29 | N29: =SUM(L29:M29) | O29: 1113210 | P29: =VLOOKUP(G29,'22F1187231'!$D$5:$J$4160,7,0)*O29-(SUM(J29:K29,M29)) | Q29: =(VLOOKUP(EOMONTH(G29,0),'22F1187231'!$D$5:$J$4160,7,0))*O29 | R29: =(VLOOKUP(G29,'22F1187231'!$D$5:$J$4160,4,0)-VLOOKUP(G29,'22F1187231'!$D$5:$J$4160,2,0))*O29 | T29: Correção | U29: =SUM(R7:R18)
A30: =CONCATENATE(C30,D30,E30) | B30: =CONCATENATE(D30,E30) | C30: =IF(D30>=1,IF(D30<=3,"1",IF(D30>=4,IF(D30<=6,"2",IF(D30>=7,IF(D30<=9,"3",IF(D30>=10,IF(D30<=12,"4","-")))))))) | D30: =MONTH(G30) | E30: =YEAR(G30) | F30: =F29+1 | G30: 45560 | H30: 0.005057 | I30: 55 | J30: =IFERROR((VLOOKUP($G30,'22F1187231'!$D$3:$N$4160,8,1))*O30,0) | K30: =VLOOKUP(G30,'22F1187231'!$D$5:$L$4163,9,0)*O30 | L30: =SUM(J30:K30) | M30: =(VLOOKUP($G30,'22F1187231'!$D$5:$N$4163,10,1))*O30 | N30: =SUM(L30:M30) | O30: 1113210 | P30: =VLOOKUP(G30,'22F1187231'!$D$5:$J$4160,7,0)*O30-(SUM(J30:K30,M30)) | Q30: =(VLOOKUP(EOMONTH(G30,0),'22F1187231'!$D$5:$J$4160,7,0))*O30 | R30: =(VLOOKUP(G30,'22F1187231'!$D$5:$J$4160,4,0)-VLOOKUP(G30,'22F1187231'!$D$5:$J$4160,2,0))*O30
A31: =CONCATENATE(C31,D31,E31) | B31: =CONCATENATE(D31,E31) | C31: =IF(D31>=1,IF(D31<=3,"1",IF(D31>=4,IF(D31<=6,"2",IF(D31>=7,IF(D31<=9,"3",IF(D31>=10,IF(D31<=12,"4","-")))))))) | D31: =MONTH(G31) | E31: =YEAR(G31) | F31: 56 | G31: 45590 | H31: 0.005124 | I31: 56 | J31: =IFERROR((VLOOKUP($G31,'22F1187231'!$D$3:$N$4160,8,1))*O31,0) | K31: =VLOOKUP(G31,'22F1187231'!$D$5:$L$4163,9,0)*O31 | L31: =SUM(J31:K31) | M31: =(VLOOKUP($G31,'22F1187231'!$D$5:$N$4163,10,1))*O31 | N31: =SUM(L31:M31) | O31: 1113210 | P31: =VLOOKUP(G31,'22F1187231'!$D$5:$J$4160,7,0)*O31-(SUM(J31:K31,M31)) | Q31: =(VLOOKUP(EOMONTH(G31,0),'22F1187231'!$D$5:$J$4160,7,0))*O31 | R31: =(VLOOKUP(G31,'22F1187231'!$D$5:$J$4160,4,0)-VLOOKUP(G31,'22F1187231'!$D$5:$J$4160,2,0))*O31
A32: =CONCATENATE(C32,D32,E32) | B32: =CONCATENATE(D32,E32) | C32: =IF(D32>=1,IF(D32<=3,"1",IF(D32>=4,IF(D32<=6,"2",IF(D32>=7,IF(D32<=9,"3",IF(D32>=10,IF(D32<=12,"4","-")))))))) | D32: =MONTH(G32) | E32: =YEAR(G32) | F32: =F31+1 | G32: 45621 | H32: 0.005179 | I32: 57 | J32: =IFERROR((VLOOKUP($G32,'22F1187231'!$D$3:$N$4160,8,1))*O32,0) | K32: =VLOOKUP(G32,'22F1187231'!$D$5:$L$4163,9,0)*O32 | L32: =SUM(J32:K32) | M32: =(VLOOKUP($G32,'22F1187231'!$D$5:$N$4163,10,1))*O32 | N32: =SUM(L32:M32) | O32: 1113210 | P32: =VLOOKUP(G32,'22F1187231'!$D$5:$J$4160,7,0)*O32-(SUM(J32:K32,M32)) | Q32: =(VLOOKUP(EOMONTH(G32,0),'22F1187231'!$D$5:$J$4160,7,0))*O32 | R32: =(VLOOKUP(G32,'22F1187231'!$D$5:$J$4160,4,0)-VLOOKUP(G32,'22F1187231'!$D$5:$J$4160,2,0))*O32
A33: =CONCATENATE(C33,D33,E33) | B33: =CONCATENATE(D33,E33) | C33: =IF(D33>=1,IF(D33<=3,"1",IF(D33>=4,IF(D33<=6,"2",IF(D33>=7,IF(D33<=9,"3",IF(D33>=10,IF(D33<=12,"4","-")))))))) | D33: =MONTH(G5) | E33: =YEAR(G5) | F33: =F32+1 | G33: 45651 | H33: 0.005331 | I33: 58 | J33: =IFERROR((VLOOKUP($G33,'22F1187231'!$D$3:$N$4160,8,1))*O33,0) | K33: =VLOOKUP(G33,'22F1187231'!$D$5:$L$4163,9,0)*O33 | L33: =SUM(J33:K33) | M33: =(VLOOKUP($G33,'22F1187231'!$D$5:$N$4163,10,1))*O33 | N33: =SUM(L33:M33) | O33: 1113210 | P33: =VLOOKUP(G33,'22F1187231'!$D$5:$J$4160,7,0)*O33-(SUM(J33:K33,M33)) | Q33: =(VLOOKUP(EOMONTH(G33,0),'22F1187231'!$D$5:$J$4160,7,0))*O33 | R33: =(VLOOKUP(G33,'22F1187231'!$D$5:$J$4160,4,0)-VLOOKUP(G33,'22F1187231'!$D$5:$J$4160,2,0))*O33 | T33: *preencher apenas as células em amarelo para informe trimestral
A34: =CONCATENATE(C34,D34,E34) | B34: =CONCATENATE(D34,E34) | C34: =IF(D34>=1,IF(D34<=3,"1",IF(D34>=4,IF(D34<=6,"2",IF(D34>=7,IF(D34<=9,"3",IF(D34>=10,IF(D34<=12,"4","-")))))))) | D34: =MONTH(G6) | E34: =YEAR(G6) | F34: =F33+1 | G34: 45682 | H34: 0.005578 | I34: 59 | J34: =IFERROR((VLOOKUP($G34,'22F1187231'!$D$3:$N$4160,8,1))*O34,0) | K34: =VLOOKUP(G34,'22F1187231'!$D$5:$L$4163,9,0)*O34 | L34: =SUM(J34:K34) | M34: =(VLOOKUP($G34,'22F1187231'!$D$5:$N$4163,10,1))*O34 | N34: =SUM(L34:M34) | O34: 1113210 | P34: =VLOOKUP(G34,'22F1187231'!$D$5:$J$4160,7,0)*O34-(SUM(J34:K34,M34)) | Q34: =(VLOOKUP(EOMONTH(G34,0),'22F1187231'!$D$5:$J$4160,7,0))*O34 | R34: =(VLOOKUP(G34,'22F1187231'!$D$5:$J$4160,4,0)-VLOOKUP(G34,'22F1187231'!$D$5:$J$4160,2,0))*O34 | T34: PAGAMENTO | U34: TRIMESTRE | V34: ANO | W34: MÊS FECHAMENTO
A35: =CONCATENATE(C35,D35,E35) | B35: =CONCATENATE(D35,E35) | C35: =IF(D35>=1,IF(D35<=3,"1",IF(D35>=4,IF(D35<=6,"2",IF(D35>=7,IF(D35<=9,"3",IF(D35>=10,IF(D35<=12,"4","-")))))))) | D35: =MONTH(G7) | E35: =YEAR(G7) | F35: =F34+1 | G35: 45713 | H35: 0.005677 | I35: 60 | J35: =IFERROR((VLOOKUP($G35,'22F1187231'!$D$3:$N$4160,8,1))*O35,0) | K35: =VLOOKUP(G35,'22F1187231'!$D$5:$L$4163,9,0)*O35 | L35: =SUM(J35:K35) | M35: =(VLOOKUP($G35,'22F1187231'!$D$5:$N$4163,10,1))*O35 | N35: =SUM(L35:M35) | O35: 1113210 | P35: =VLOOKUP(G35,'22F1187231'!$D$5:$J$4160,7,0)*O35-(SUM(J35:K35,M35)) | Q35: =(VLOOKUP(EOMONTH(G35,0),'22F1187231'!$D$5:$J$4160,7,0))*O35 | R35: =(VLOOKUP(G35,'22F1187231'!$D$5:$J$4160,4,0)-VLOOKUP(G35,'22F1187231'!$D$5:$J$4160,2,0))*O35 | U35: 3 | V35: 2022 | W35: =U35*2
A36: =CONCATENATE(C36,D36,E36) | B36: =CONCATENATE(D36,E36) | C36: =IF(D36>=1,IF(D36<=3,"1",IF(D36>=4,IF(D36<=6,"2",IF(D36>=7,IF(D36<=9,"3",IF(D36>=10,IF(D36<=12,"4","-")))))))) | D36: =MONTH(G8) | E36: =YEAR(G8) | F36: =F35+1 | G36: 45741 | H36: 0.005756 | I36: 61 | J36: =IFERROR((VLOOKUP($G36,'22F1187231'!$D$3:$N$4160,8,1))*O36,0) | K36: =VLOOKUP(G36,'22F1187231'!$D$5:$L$4163,9,0)*O36 | L36: =SUM(J36:K36) | M36: =(VLOOKUP($G36,'22F1187231'!$D$5:$N$4163,10,1))*O36 | N36: =SUM(L36:M36) | O36: 1113210 | P36: =VLOOKUP(G36,'22F1187231'!$D$5:$J$4160,7,0)*O36-(SUM(J36:K36,M36)) | Q36: =(VLOOKUP(EOMONTH(G36,0),'22F1187231'!$D$5:$J$4160,7,0))*O36 | R36: =(VLOOKUP(G36,'22F1187231'!$D$5:$J$4160,4,0)-VLOOKUP(G36,'22F1187231'!$D$5:$J$4160,2,0))*O36 | T36: Juros | U36: =SUMIFS($J$1:$J$140,$C$1:$C$140,$U$35,E1:E140,$V$35)
A37: =CONCATENATE(C37,D37,E37) | B37: =CONCATENATE(D37,E37) | C37: =IF(D37>=1,IF(D37<=3,"1",IF(D37>=4,IF(D37<=6,"2",IF(D37>=7,IF(D37<=9,"3",IF(D37>=10,IF(D37<=12,"4","-")))))))) | D37: =MONTH(G9) | E37: =YEAR(G9) | F37: =F36+1 | G37: 45772 | H37: 0.005822 | I37: 62 | J37: =IFERROR((VLOOKUP($G37,'22F1187231'!$D$3:$N$4160,8,1))*O37,0) | K37: =VLOOKUP(G37,'22F1187231'!$D$5:$L$4163,9,0)*O37 | L37: =SUM(J37:K37) | M37: =(VLOOKUP($G37,'22F1187231'!$D$5:$N$4163,10,1))*O37 | N37: =SUM(L37:M37) | O37: 1113210 | P37: =VLOOKUP(G37,'22F1187231'!$D$5:$J$4160,7,0)*O37-(SUM(J37:K37,M37)) | Q37: =(VLOOKUP(EOMONTH(G37,0),'22F1187231'!$D$5:$J$4160,7,0))*O37 | R37: =(VLOOKUP(G37,'22F1187231'!$D$5:$J$4160,4,0)-VLOOKUP(G37,'22F1187231'!$D$5:$J$4160,2,0))*O37 | T37: Amortização | U37: =SUMIFS($K$4:$K$140,$C$4:$C$140,$U$35,E4:E140,$V$35)
A38: =CONCATENATE(C38,D38,E38) | B38: =CONCATENATE(D38,E38) | C38: =IF(D38>=1,IF(D38<=3,"1",IF(D38>=4,IF(D38<=6,"2",IF(D38>=7,IF(D38<=9,"3",IF(D38>=10,IF(D38<=12,"4","-")))))))) | D38: =MONTH(G10) | E38: =YEAR(G10) | F38: =F37+1 | G38: 45802 | H38: 0.005889 | I38: 63 | J38: =IFERROR((VLOOKUP($G38,'22F1187231'!$D$3:$N$4160,8,1))*O38,0) | K38: =VLOOKUP(G38,'22F1187231'!$D$5:$L$4163,9,0)*O38 | L38: =SUM(J38:K38) | M38: =(VLOOKUP($G38,'22F1187231'!$D$5:$N$4163,10,1))*O38 | N38: =SUM(L38:M38) | O38: 1113210 | P38: =VLOOKUP(G38,'22F1187231'!$D$5:$J$4160,7,0)*O38-(SUM(J38:K38,M38)) | Q38: =(VLOOKUP(EOMONTH(G38,0),'22F1187231'!$D$5:$J$4160,7,0))*O38 | R38: =(VLOOKUP(G38,'22F1187231'!$D$5:$J$4160,4,0)-VLOOKUP(G38,'22F1187231'!$D$5:$J$4160,2,0))*O38 | T38: Amex | U38: =SUMIFS($M$3:$M$140,$C$3:$C$140,$U$35,E3:E140,$V$35)
A39: =CONCATENATE(C39,D39,E39) | B39: =CONCATENATE(D39,E39) | C39: =IF(D39>=1,IF(D39<=3,"1",IF(D39>=4,IF(D39<=6,"2",IF(D39>=7,IF(D39<=9,"3",IF(D39>=10,IF(D39<=12,"4","-")))))))) | D39: =MONTH(G11) | E39: =YEAR(G11) | F39: =F38+1 | G39: 45833 | H39: 0.005957 | I39: 64 | J39: =IFERROR((VLOOKUP($G39,'22F1187231'!$D$3:$N$4160,8,1))*O39,0) | K39: =VLOOKUP(G39,'22F1187231'!$D$5:$L$4163,9,0)*O39 | L39: =SUM(J39:K39) | M39: =(VLOOKUP($G39,'22F1187231'!$D$5:$N$4163,10,1))*O39 | N39: =SUM(L39:M39) | O39: 1113210 | P39: =VLOOKUP(G39,'22F1187231'!$D$5:$J$4160,7,0)*O39-(SUM(J39:K39,M39)) | Q39: =(VLOOKUP(EOMONTH(G39,0),'22F1187231'!$D$5:$J$4160,7,0))*O39 | R39: =(VLOOKUP(G39,'22F1187231'!$D$5:$J$4160,4,0)-VLOOKUP(G39,'22F1187231'!$D$5:$J$4160,2,0))*O39 | T39: Amort + Amex | U39: =SUM(U37:U38)
A40: =CONCATENATE(C40,D40,E40) | B40: =CONCATENATE(D40,E40) | C40: =IF(D40>=1,IF(D40<=3,"1",IF(D40>=4,IF(D40<=6,"2",IF(D40>=7,IF(D40<=9,"3",IF(D40>=10,IF(D40<=12,"4","-")))))))) | D40: =MONTH(G12) | E40: =YEAR(G12) | F40: =F39+1 | G40: 45863 | H40: 0.006027 | I40: 65 | J40: =IFERROR((VLOOKUP($G40,'22F1187231'!$D$3:$N$4160,8,1))*O40,0) | K40: =VLOOKUP(G40,'22F1187231'!$D$5:$L$4163,9,0)*O40 | L40: =SUM(J40:K40) | M40: =(VLOOKUP($G40,'22F1187231'!$D$5:$N$4163,10,1))*O40 | N40: =SUM(L40:M40) | O40: 1113210 | P40: =VLOOKUP(G40,'22F1187231'!$D$5:$J$4160,7,0)*O40-(SUM(J40:K40,M40)) | Q40: =(VLOOKUP(EOMONTH(G40,0),'22F1187231'!$D$5:$J$4160,7,0))*O40 | R40: =(VLOOKUP(G40,'22F1187231'!$D$5:$J$4160,4,0)-VLOOKUP(G40,'22F1187231'!$D$5:$J$4160,2,0))*O40 | T40: Saldo Operação | U40: =IFERROR(VLOOKUP(CONCATENATE(U35,W35,V35),$A$3:$R$999,15,0),"-")
...

Sheet IPCA
A1: EVENTO | B1: MÊS/ANO | C1: VARIAÇÃO
A2: 1 | B2: 44706 | C2: 0.0047000727
A3: =A2+1 | B3: 44737 | C3: 0.0067005776
A4: =A3+1 | B4: 44767 | C4: -0.0068000341
A5: =A4+1 | B5: 44798 | C5: -0.003599529
A6: =A5+1 | B6: 44829 | C6: -0.0029003564
A7: =A6+1 | B7: 44859 | C7: 0.0059007839
A8: =A7+1 | B8: 44890 | C8: 0.0040996078
A9: =A8+1 | B9: 44920 | C9: 0.0061996829
A10: =A9+1 | B10: 44951 | C10: 0.0052995865
A11: =A10+1 | B11: 44982 | C11: 0.008399914
A12: =A11+1 | B12: 45010 | C12: 0.0071003357
A13: =A12+1 | B13: 45041 | C13: 0.0061001533
A14: =A13+1 | B14: 45071 | C14: 0.0022992516
... A36: =A35+1 | B36: 45741 | C36: 0.0056002543
A37: =A36+1 | B37: 45772 | C37: =C36
A38: =A37+1 | B38: 45802 | C38: =C37
A39: =A38+1 | B39: 45833 | C39: =C38
A40: =A39+1 | B40: 45863 | C40: =C39
A41: =A40+1 | B41: 45894 | C41: =C40
A42: =A41+1 | B42: 45925 | C42: =C41
A43: =A42+1 | B43: 45955 | C43: =C42
A44: =A43+1 | B44: 45986 | C44: =C43
A45: =A44+1 | B45: 46016 | C45: =C44
A46: =A45+1 | B46: 46047 | C46: =C45
A47: =A46+1 | B47: 46078 | C47: =C46
A48: =A47+1 | B48: 46106 | C48: =C47
... A140: =A139+1 | B140: 48908 | C140: =C139

Sheet  Nexus
C4: RELATÓRIO DE PAGAMENTOS
C6: CERTIFICADO DE RECEBÍVEIS IMOBILIÁRIOS
F8: =CONCATENATE("Evento ",F23)
F9: =F24
E11: Série: | F11: 46ª
B12: Data da Emissão: | C12: 43906 | E12: Emissão: | F12: 1ª
B13: PU de Emissão: | C13: 1 | E13: Código IF (CETIP): | F13: 20F1187231 | K13: QUANTIDADE | L13: JUROS | M13: AMORT | N13: AMEX | O13: TOTAL
B14: CRI emitidos: | C14: 100000000 | E14: Código ISIN: | L14: =C23 | M14: =C25 | N14: =C26
B15: CRI integralizados: | C15: =K17 | J15: Investidor 01: | K15: 2541355 | L15: =IFERROR($L$14*K15,0) | M15: =$M$14*K15 | N15: =N14*K15 | O15: =SUM(L15:N15)
B16: Valor total de Emissão: | C16: =C14*C13 | E16: Pagamentos | J16: Investidor 02: | K16: 635339 | L16: =IFERROR($L$14*K16,0) | M16: =$M$14*K16 | N16: =N14*K16 | O16: =SUM(L16:N16)
B17: Taxa Remuneração: | C17: 0.095 | E17: Remuneração: | F17: Mensal | J17: TOTAL | K17: =SUM(K15:K16) | L17: =SUM(L15:L16) | M17: =SUM(M15:M16) | O17: =SUM(L17:N17)
B18: Indexador Correção: | C18: IPCA | E18: Correção: | F18: Mensal
B19: Dia dos Eventos: | C19: 25 | E19: Amortização: | F19: Mensal
B23: Juros por Unidade: | C23: =VLOOKUP(F24,'22F1187231'!D5:N4161,8,0) | E23: Evento: | F23: 1
B24: % Amortização: | C24: =VLOOKUP(F23,'Amort TS'!F4:H140,3,0) | E24: Data do Evento: | F24: 45376
B25: Amortização por Unidade: | C25: =VLOOKUP(F24,'22F1187231'!D5:N4161,9,0) | E25: Pagamentos
B26: Amortização Extraordinária por Unidade: | C26: =VLOOKUP(F24,'22F1187231'!D5:N4161,10,0) | E26: Investidor 01: | F26: =$C$27*K15
B27: Pagamento Total por Unidade: | C27: =IFERROR(SUM(C26+C25+C23),0) | E27: Investidor 02: | F27: =$C$27*K16
B28: Pagamento Total CRI Circulação: | C28: =C27*$C$15
B32: Saldo Devedor Unitário | C32: =VLOOKUP(F24,'22F1187231'!D5:N4161,11,0)
B33: Saldo Devedor Total | C33: =C32*$C$15
B36: José Roque | C36: (41) 3027-2040 / 99931-2040 | E36: jose.roque@ethosgroup.com.br
B37: Andressa, Laura e Amanda | C37: (41) 3149-7103 | E37: securitizacao@ethosgroup.com.br
B38: Ricardo dos Santos Rosa | C38: (41) 3149-7103 | E38: ricardo.rosa@ethosgroup.com.br
B39: Edinéia Boruck | C39: (41) 3149-7103 | E39: edineia.boruck@ethosgroup.com.br

Sheet Filtros Estatisticos
C1: 08/07/2025 16:10:08
A2: 1 | B2: 1
A3: 5 | B3: 5
A4: 2 | B4: 2
A5: 6 | B5: 6

Sheet PU Operacao
B2: 152
B3: 252
B4: 54598.186
B5: 05/08/2025 23:10:37
A6: 2025-08-06 | B6: 165 | C6: 100000
